Workbook

Sheet 1. Press Assumptions
A1: PRESS CAPITAL -- Fund I ASSUMPTIONS
A2: All blue cells are adjustable inputs. Black cells on gray are calculated.
A4: FUND PARAMETERS
A5: Fund Size ($) | B5: 150000000
A6: Number of Deals | B6: 5
A7: ARR per Deal ($) | B7: 25000000
A8: Entry Multiple (x ARR) | B8: =SUMPRODUCT('3. Deal Allocation'!B5:B9,'3. Deal Allocation'!C5:C9)/SUM('3. Deal Allocation'!B5:B9) -> 1.5762712
A9: Capital per Deal ($) | B9: 41666667 | E9: ARR x Entry Multiple (auto)
A10: Total Capital Deployed ($) | B10: 150000000 | E10: Deals x Capital per Deal (auto)
A11: Asset Deal % (50% rev haircut Y1) | B11: 0.25
A12: Share Deal % | B12: 0.75 | E12: 1 - Asset Deal %
A13: Leverage / Debt | B13: Zero | E13: No debt at fund or portfolio company level. All cash acquisitions.
A15: RETENTION & GROWTH
A16: Net Dollar Retention -- Base Case | B16: 0.85
A17: Net Dollar Retention -- Homerun | B17: 0.95
A18: Net Dollar Retention -- Looser | B18: 0.8 | E18: Conservative / stress test scenario
A19: NCA % -- Base Case | B19: 0
A20: NCA % -- Homerun | B20: 0.05
A21: Scenario Toggle (1=Base, 2=Homerun) | B21: 1 | E21: 1=Base, 2=Homerun, 3=Looser
A22: Active Retention Rate | B22: 0.85
A23: Active NCA Rate | B23: 0
A25: MARGIN MODEL
A26: Net Margin (flat, all years) | B26: 0.625 | E26: Used in flat-margin tabs (3a-3d). Set to 0 to use component costs.
A28: COST STRUCTURE
A29: All companies assumed breakeven at entry. Adjust per-deal entry margin on Tab 2.
A30: COGS | B30: 0.1 | E30: Ramps from 25% at close to 10% over 6 months
A31: Vendor Costs | B31: 0.05 | E31: Ramps from 10% at close to 5% over 6 months
A32: Corporate Allocation | B32: 0.06 | E32: Flat
A33: Legacy Headcount Expenses | B33: 0 | E33: Acquired company staff. 50% cut day 1, 90% by M6, 100% by M24. Rate derived from entry profit per deal.
A34: Salary Overhead Loading | B34: 0.3 | E34: On top of base salaries
A35: Bonus Pool Threshold | B35: 1 | C35: Set to 100% per GP -- no bonus pool. All margin upside flows to investors. | E35: Included in OpEx. Everything above 62.5% EBITDA margin goes to team.
A37: WATERFALL & DISTRIBUTION
A38: Phase 1: Return of Capital (x) | B38: 1 | E38: 100% to LPs until 1x returned
A39: Preferred Return (Annual) | B39: 0.1 | E39: 10% pref on unreturned capital
A40: Tier 2: LP Split % (1x-2x) | B40: 0.8 | E40: HoldCo gets 20%
A41: Tier 3: LP Split % (2x-3x) | B41: 0.8 | E41: HoldCo gets 25%
A42: Tier 4: LP Split % (above 3x) | B42: 0.8 | E42: HoldCo gets 30% -- perpetual
A43: Mgmt Fee Schedule | B43: 2% Y1 only | E43: 0% after Y1 once 3 deals deployed
A45: TIERED WATERFALL THRESHOLDS
A46: Tier | B46: Threshold (x) | C46: LP Split %
...

Sheet 2. LP Economics
A1: LP ECONOMICS BY COMMITMENT SIZE (Fund I -- 50% Recycle)
A2: Live from _Engine_R50 (50% recycle). Returns identical across commitment sizes; cash scales linearly.
C5: $5M | F5: $10M | I5: $25M
A7: FUND PARTICIPATION
A8: Commitment | C8: 5 | F8: 10 | I8: 25
A9: Payback (months) | C9: TBD | F9: TBD | I9: TBD
A11: 10-YEAR RETURNS
A12: LP Net IRR (Staged) | C12: =_Engine_R50!$B$277 -> 0.17777176 | F12: =_Engine_R50!$B$277 -> 0.17777176 | I12: =_Engine_R50!$B$277 -> 0.17777176
A13: LP MOIC / DPI | C13: =_Engine_R50!$B$254 -> 2.3673409 | F13: =_Engine_R50!$B$254 -> 2.3673409 | I13: =_Engine_R50!$B$254 -> 2.3673409
A14: Cash Distributed | C14: =C13*C8 -> 11.836704 | F14: =F13*F8 -> 23.673409 | I14: =I13*I8 -> 59.183522
A16: 15-YEAR RETURNS
A17: LP Net IRR (Staged) | C17: =_Engine_R50!$B$276 -> 0.19472592 | F17: =_Engine_R50!$B$276 -> 0.19472592 | I17: =_Engine_R50!$B$276 -> 0.19472592
A18: LP MOIC / DPI | C18: =_Engine_R50!$B$252 -> 2.9981273 | F18: =_Engine_R50!$B$252 -> 2.9981273 | I18: =_Engine_R50!$B$252 -> 2.9981273
A19: Total Cash | C19: =C18*C8 -> 14.990636 | F19: =F18*F8 -> 29.981273 | I19: =I18*I8 -> 74.953182
A21: NOTE: returns above are identical across commitment sizes (the model has no LP class differentiation).
A22: See Tab 11 for NDR x Margin joint sensitivity. See Tab 20 for quarterly cash schedule.
B31: 0 | C31: 0 | D31: 0 | E31: 0 | F31: 0 | G31: 0 | H31: 0 | I31: 0 | J31: 0
D32: 0 | G32: 0 | J32: 0
D33: 0 | G33: 0 | J33: 0
B45: 0 | E45: 0 | H45: 0

Sheet 3. Deal Allocation
A1: PRESS CAPITAL -- DEAL ALLOCATION
A2: 4 initial deals ($100M ARR, blended 1.50x) + 1 recycled ($18M ARR @ 2.0x). Seller-paid severance nets price down.
A4: Deal | B4: ARR ($mm) | C4: Entry Mult | D4: Gross Price | E4: Sev Disc | F4: Net Price | G4: NDR | H4: Entry Profit | I4: Close Mo
A5: #1 | B5: ='1. Press Assumptions'!$D$89 -> 25 | C5: ='1. Press Assumptions'!$E$89 -> 2 | D5: =B5*C5 -> 50 | E5: =B5*0.1154*0.5 -> 1.4425 | F5: =D5-E5 -> 48.5575 | G5: 0.95 | H5: 0 | I5: ="M"&'1. Press Assumptions'!$K$89 -> M4
A6: #2 | B6: ='1. Press Assumptions'!$D$90 -> 25 | C6: ='1. Press Assumptions'!$E$90 -> 1.5 | D6: =B6*C6 -> 37.5 | E6: =B6*0.1154*0.5 -> 1.4425 | F6: =D6-E6 -> 36.0575 | G6: 0.9 | H6: 0 | I6: ="M"&'1. Press Assumptions'!$K$90 -> M8
A7: #3 | B7: ='1. Press Assumptions'!$D$91 -> 25 | C7: ='1. Press Assumptions'!$E$91 -> 1.25 | D7: =B7*C7 -> 31.25 | E7: =B7*0.1154*0.5 -> 1.4425 | F7: =D7-E7 -> 29.8075 | G7: 0.85 | H7: 0 | I7: ="M"&'1. Press Assumptions'!$K$91 -> M12
A8: #4 | B8: ='1. Press Assumptions'!$D$92 -> 25 | C8: ='1. Press Assumptions'!$E$92 -> 1.25 | D8: =B8*C8 -> 31.25 | E8: =B8*0.1154*0.5 -> 1.4425 | F8: =D8-E8 -> 29.8075 | G8: 0.85 | H8: 0 | I8: ="M"&'1. Press Assumptions'!$K$92 -> M16
A9: #5 (recycled) | B9: ='1. Press Assumptions'!$D$93 -> 18 | C9: ='1. Press Assumptions'!$E$93 -> 2 | D9: =B9*C9 -> 36 | E9: =B9*0.1154*0.5 -> 1.0386 | F9: =D9-E9 -> 34.9614 | G9: 0.95 | H9: 0 | I9: ="M"&'1. Press Assumptions'!$K$93 -> M32
A11: TOTAL | B11: =SUM(B5:B9) -> 118 | D11: =SUM(D5:D9) -> 186 | E11: =SUM(E5:E9) -> 6.8086 | F11: =SUM(F5:F9) -> 179.1914
A13: RECYCLED DEAL (50% retention through close; 120% deployment cap)
A14: Deal | B14: ARR ($mm) | C14: Entry Mult | D14: Gross Price | E14: Sev Disc | F14: Net Price | G14: NDR | H14: Entry Profit | I14: Close Mo
A15: #6 | B15: ='1. Press Assumptions'!$D$96 -> 0 | C15: ='1. Press Assumptions'!$E$96 -> 2 | D15: =B15*C15 -> 0 | E15: =B15*0.1154*0.5 -> 0 | F15: =D15-E15 -> 0 | G15: 0.95 | H15: 0 | I15: ="M"&'1. Press Assumptions'!$K$96 -> M999
A16: #7 | B16: ='1. Press Assumptions'!$D$97 -> 0 | C16: ='1. Press Assumptions'!$E$97 -> 2 | D16: =B16*C16 -> 0 | E16: =B16*0.1154*0.5 -> 0 | F16: =D16-E16 -> 0 | H16: 0 | I16: ="M"&'1. Press Assumptions'!$K$97 -> M999
A17: #8 | B17: ='1. Press Assumptions'!$D$98 -> 0 | C17: ='1. Press Assumptions'!$E$98 -> 2 | D17: =B17*C17 -> 0 | E17: =B17*0.1154*0.5 -> 0 | F17: =D17-E17 -> 0 | H17: 0 | I17: ="M"&'1. Press Assumptions'!$K$98 -> M999
A18: #9 | B18: ='1. Press Assumptions'!$D$99 -> 0 | C18: ='1. Press Assumptions'!$E$99 -> 2 | D18: =B18*C18 -> 0 | E18: =B18*0.1154*0.5 -> 0 | F18: =D18-E18 -> 0 | H18: 0 | I18: ="M"&'1. Press Assumptions'!$K$99 -> M999
A42: Green = premium (profitable + growing). Gold = par. Red = distress discount.

Sheet 4b. Annual P&L (Recycle)
A1: PRESS CAPITAL -- FUND I P&L | 50% RECYCLE x 36mo
A2: 8 deals @ $24M ARR. 50% retained M1-36.. LIVE from _Engine_R50.
A3: ($mm) | B3: Total | C3: Year 1 | D3: Year 2 | E3: Year 3 | F3: Year 4 | G3: Year 5 | H3: Year 6 | I3: Year 7 | J3: Year 8 | K3: Year 9 | L3: Year 10 | M3: Year 11 | N3: Year 12 | O3: Year 13 | P3: Year 14 | Q3: Year 15
A5: Revenue | B5: =SUM(C5:Q5) -> 888.49958 | C5: =_Engine_R50!B215 -> 30.752733 | D5: =_Engine_R50!B216 -> 86.999352 | E5: =_Engine_R50!B217 -> 90.334889 | F5: =_Engine_R50!B218 -> 90.934577 | G5: =_Engine_R50!B219 -> 82.060217 | H5: =_Engine_R50!B220 -> 74.232532 | I5: =_Engine_R50!B221 -> 67.313364 | J5: =_Engine_R50!B222 -> 61.183873 | K5: =_Engine_R50!B223 -> 55.741759 | L5: =_Engine_R50!B224 -> 50.898885 | M5: =_Engine_R50!B225 -> 46.579249 | N5: =_Engine_R50!B226 -> 42.717253 | O5: =_Engine_R50!B227 -> 39.25622 | P5: =_Engine_R50!B228 -> 36.147132 | Q5: =_Engine_R50!B229 -> 33.347546
A6: Cost of Goods Sold | B6: =SUM(C6:Q6) -> 88.849958 | C6: =_Engine_R50!C215 -> 3.0752733 | D6: =_Engine_R50!C216 -> 8.6999352 | E6: =_Engine_R50!C217 -> 9.0334889 | F6: =_Engine_R50!C218 -> 9.0934577 | G6: =_Engine_R50!C219 -> 8.2060217 | H6: =_Engine_R50!C220 -> 7.4232532 | I6: =_Engine_R50!C221 -> 6.7313364 | J6: =_Engine_R50!C222 -> 6.1183873 | K6: =_Engine_R50!C223 -> 5.5741759 | L6: =_Engine_R50!C224 -> 5.0898885 | M6: =_Engine_R50!C225 -> 4.6579249 | N6: =_Engine_R50!C226 -> 4.2717253 | O6: =_Engine_R50!C227 -> 3.925622 | P6: =_Engine_R50!C228 -> 3.6147132 | Q6: =_Engine_R50!C229 -> 3.3347546
A7: Gross Profit | B7: =SUM(C7:Q7) -> 799.64962 | C7: =C5-C6 -> 27.677459 | D7: =D5-D6 -> 78.299417 | E7: =E5-E6 -> 81.3014 | F7: =F5-F6 -> 81.841119 | G7: =G5-G6 -> 73.854195 | H7: =H5-H6 -> 66.809279 | I7: =I5-I6 -> 60.582027 | J7: =J5-J6 -> 55.065485 | ... Q7: =Q5-Q6 -> 30.012791
A9: Operating Expenses
A10: Vendor Costs | B10: =SUM(C10:Q10) -> 44.424979 | C10: =_Engine_R50!D215 -> 1.5376366 | D10: =_Engine_R50!D216 -> 4.3499676 | E10: =_Engine_R50!D217 -> 4.5167444 | F10: =_Engine_R50!D218 -> 4.5467289 | G10: =_Engine_R50!D219 -> 4.1030109 | H10: =_Engine_R50!D220 -> 3.7116266 | I10: =_Engine_R50!D221 -> 3.3656682 | J10: =_Engine_R50!D222 -> 3.0591936 | K10: =_Engine_R50!D223 -> 2.7870879 | L10: =_Engine_R50!D224 -> 2.5449442 | M10: =_Engine_R50!D225 -> 2.3289625 | N10: =_Engine_R50!D226 -> 2.1358626 | O10: =_Engine_R50!D227 -> 1.962811 | P10: =_Engine_R50!D228 -> 1.8073566 | Q10: =_Engine_R50!D229 -> 1.6673773
A11: Corporate Allocation | B11: =SUM(C11:Q11) -> 53.309975 | C11: =_Engine_R50!E215 -> 1.845164 | D11: =_Engine_R50!E216 -> 5.2199611 | E11: =_Engine_R50!E217 -> 5.4200933 | F11: =_Engine_R50!E218 -> 5.4560746 | G11: =_Engine_R50!E219 -> 4.923613 | H11: =_Engine_R50!E220 -> 4.4539519 | I11: =_Engine_R50!E221 -> 4.0388018 | J11: =_Engine_R50!E222 -> 3.6710324 | K11: =_Engine_R50!E223 -> 3.3445055 | L11: =_Engine_R50!E224 -> 3.0539331 | M11: =_Engine_R50!E225 -> 2.7947549 | N11: =_Engine_R50!E226 -> 2.5630352 | O11: =_Engine_R50!E227 -> 2.3553732 | P11: =_Engine_R50!E228 -> 2.1688279 | Q11: =_Engine_R50!E229 -> 2.0008528
A12: Team Compensation | B12: =SUM(C12:Q12) -> 110.33479 | C12: =_Engine_R50!F215 -> 3.4572699 | D12: =_Engine_R50!F216 -> 7.5965239 | E12: =_Engine_R50!F217 -> 7.637 | F12: =_Engine_R50!F218 -> 7.637 | G12: =_Engine_R50!F219 -> 7.637 | H12: =_Engine_R50!F220 -> 7.637 | I12: =_Engine_R50!F221 -> 7.637 | J12: =_Engine_R50!F222 -> 7.637 | K12: =_Engine_R50!F223 -> 7.637 | L12: =_Engine_R50!F224 -> 7.637 | M12: =_Engine_R50!F225 -> 7.637 | N12: =_Engine_R50!F226 -> 7.637 | O12: =_Engine_R50!F227 -> 7.637 | P12: =_Engine_R50!F228 -> 7.637 | Q12: =_Engine_R50!F229 -> 7.637
A13: Legacy Headcount Expenses | B13: =SUM(C13:Q13) -> 30.916667 | C13: =_Engine_R50!G215 -> 9.9555556 | D13: =_Engine_R50!G216 -> 12.392593 | E13: =_Engine_R50!G217 -> 6.312963 | F13: =_Engine_R50!G218 -> 1.9833333 | G13: =_Engine_R50!G219 -> 0.27222222 | H13: =_Engine_R50!G220 -> 0 | I13: =_Engine_R50!G221 -> 0 | J13: =_Engine_R50!G222 -> 0 | K13: =_Engine_R50!G223 -> 0 | L13: =_Engine_R50!G224 -> 0 | M13: =_Engine_R50!G225 -> 0 | N13: =_Engine_R50!G226 -> 0 | O13: =_Engine_R50!G227 -> 0 | P13: =_Engine_R50!G228 -> 0 | Q13: =_Engine_R50!G229 -> 0
A14: Bonus Pool | B14: =SUM(C14:Q14) -> 0 | C14: =_Engine_R50!H215 -> 0 | D14: =_Engine_R50!H216 -> 0 | E14: =_Engine_R50!H217 -> 0 | F14: =_Engine_R50!H218 -> 0 | G14: =_Engine_R50!H219 -> 0 | H14: =_Engine_R50!H220 -> 0 | I14: =_Engine_R50!H221 -> 0 | J14: =_Engine_R50!H222 -> 0 | K14: =_Engine_R50!H223 -> 0 | L14: =_Engine_R50!H224 -> 0 | M14: =_Engine_R50!H225 -> 0 | N14: =_Engine_R50!H226 -> 0 | O14: =_Engine_R50!H227 -> 0 | P14: =_Engine_R50!H228 -> 0 | Q14: =_Engine_R50!H229 -> 0
A15: Total Operating Expenses | B15: =SUM(C15:Q15) -> 238.98641 | C15: =C10+C11+C12+C13+C14 -> 16.795626 | D15: =D10+D11+D12+D13+D14 -> 29.559045 | E15: =E10+E11+E12+E13+E14 -> 23.886801 | F15: =F10+F11+F12+F13+F14 -> 19.623137 | G15: =G10+G11+G12+G13+G14 -> 16.935846 | H15: =H10+H11+H12+H13+H14 -> 15.802579 | I15: =I10+I11+I12+I13+I14 -> 15.04147 | J15: =J10+J11+J12+J13+J14 -> 14.367226 | ... Q15: =Q10+Q11+Q12+Q13+Q14 -> 11.30523
A17: EBITDA | B17: =SUM(C17:Q17) -> 560.66321 | C17: =_Engine_R50!I215 -> 10.881833 | D17: =_Engine_R50!I216 -> 48.740372 | E17: =_Engine_R50!I217 -> 57.414599 | F17: =_Engine_R50!I218 -> 62.217983 | G17: =_Engine_R50!I219 -> 56.918349 | H17: =_Engine_R50!I220 -> 51.0067 | I17: =_Engine_R50!I221 -> 45.540557 | J17: =_Engine_R50!I222 -> 40.698259 | K17: =_Engine_R50!I223 -> 36.398989 | L17: =_Engine_R50!I224 -> 32.573119 | M17: =_Engine_R50!I225 -> 29.160607 | N17: =_Engine_R50!I226 -> 26.10963 | O17: =_Engine_R50!I227 -> 23.375414 | P17: =_Engine_R50!I228 -> 20.919234 | Q17: =_Engine_R50!I229 -> 18.707561
A18: EBITDA Margin | B18: =B17/B5 -> 0.63102248 | C18: =IF(C5=0,0,C17/C5) -> 0.35384931 | D18: =IF(D5=0,0,D17/D5) -> 0.56023833 | E18: =IF(E5=0,0,E17/E5) -> 0.63557502 | F18: =IF(F5=0,0,F17/F5) -> 0.68420599 | G18: =IF(G5=0,0,G17/G5) -> 0.69361685 | H18: =IF(H5=0,0,H17/H5) -> 0.68712058 | I18: =IF(I5=0,0,I17/I5) -> 0.67654556 | J18: =IF(J5=0,0,J17/J5) -> 0.66517953 | ... Q18: =IF(Q5=0,0,Q17/Q5) -> 0.56098765
A20: Severance (Press 50%) | B20: =SUM(C20:Q20) -> 12.25 | C20: =_Engine_R50!J215 -> 7.35 | D20: =_Engine_R50!J216 -> 2.45 | E20: =_Engine_R50!J217 -> 2.45 | F20: =_Engine_R50!J218 -> 0 | G20: =_Engine_R50!J219 -> 0 | H20: =_Engine_R50!J220 -> 0 | I20: =_Engine_R50!J221 -> 0 | J20: =_Engine_R50!J222 -> 0 | K20: =_Engine_R50!J223 -> 0 | L20: =_Engine_R50!J224 -> 0 | M20: =_Engine_R50!J225 -> 0 | N20: =_Engine_R50!J226 -> 0 | O20: =_Engine_R50!J227 -> 0 | P20: =_Engine_R50!J228 -> 0 | Q20: =_Engine_R50!J229 -> 0
A21: Operating Income | B21: =B17-B20 -> 548.41321 | C21: =C17-C20 -> 3.5318334 | D21: =D17-D20 -> 46.290372 | E21: =E17-E20 -> 54.964599 | F21: =F17-F20 -> 62.217983 | G21: =G17-G20 -> 56.918349 | H21: =H17-H20 -> 51.0067 | I21: =I17-I20 -> 45.540557 | ... Q21: =Q17-Q20 -> 18.707561
A23: Management Fee | B23: =SUM(C23:Q23) -> 4.5 | C23: =_Engine_R50!K215 -> 3 | D23: =_Engine_R50!K216 -> 1.5 | E23: =_Engine_R50!K217 -> 0 | F23: =_Engine_R50!K218 -> 0 | G23: =_Engine_R50!K219 -> 0 | H23: =_Engine_R50!K220 -> 0 | I23: =_Engine_R50!K221 -> 0 | J23: =_Engine_R50!K222 -> 0 | K23: =_Engine_R50!K223 -> 0 | L23: =_Engine_R50!K224 -> 0 | M23: =_Engine_R50!K225 -> 0 | N23: =_Engine_R50!K226 -> 0 | O23: =_Engine_R50!K227 -> 0 | P23: =_Engine_R50!K228 -> 0 | Q23: =_Engine_R50!K229 -> 0
A24: Retained for Recycling (50%) | B24: =SUM(C24:Q24) -> 42.837043 | C24: =_Engine_R50!M215 -> 2.9830484 | D24: =_Engine_R50!M216 -> 22.395186 | E24: =_Engine_R50!M217 -> 17.458808 | F24: =_Engine_R50!M218 -> 0 | G24: =_Engine_R50!M219 -> 0 | H24: =_Engine_R50!M220 -> 0 | I24: =_Engine_R50!M221 -> 0 | J24: =_Engine_R50!M222 -> 0 | K24: =_Engine_R50!M223 -> 0 | L24: =_Engine_R50!M224 -> 0 | M24: =_Engine_R50!M225 -> 0 | N24: =_Engine_R50!M226 -> 0 | O24: =_Engine_R50!M227 -> 0 | P24: =_Engine_R50!M228 -> 0 | Q24: =_Engine_R50!M229 -> 0
A25: Distributable Cash | B25: =SUM(C25:Q25) -> 508.95181 | C25: =_Engine_R50!P215 -> -2.451215 | D25: =_Engine_R50!P216 -> 22.395186 | E25: =_Engine_R50!P217 -> 45.381434 | F25: =_Engine_R50!P218 -> 62.217983 | G25: =_Engine_R50!P219 -> 56.918349 | H25: =_Engine_R50!P220 -> 51.0067 | I25: =_Engine_R50!P221 -> 45.540557 | J25: =_Engine_R50!P222 -> 40.698259 | K25: =_Engine_R50!P223 -> 36.398989 | L25: =_Engine_R50!P224 -> 32.573119 | M25: =_Engine_R50!P225 -> 29.160607 | N25: =_Engine_R50!P226 -> 26.10963 | O25: =_Engine_R50!P227 -> 23.375414 | P25: =_Engine_R50!P228 -> 20.919234 | Q25: =_Engine_R50!P229 -> 18.707561
A26: Cumulative Distributable | B26: =Q26 -> 508.95181 | C26: =C25 -> -2.451215 | D26: =C26+D25 -> 19.943971 | E26: =D26+E25 -> 65.325405 | F26: =E26+F25 -> 127.54339 | G26: =F26+G25 -> 184.46174 | H26: =G26+H25 -> 235.46844 | I26: =H26+I25 -> 281.00899 | J26: =I26+J25 -> 321.70725 | K26: =J26+K25 -> 358.10624 | ... Q26: =P26+Q25 -> 508.95181

Sheet 4d. Monthly P&L (Recycle)
A1: MONTHLY P&L | 8 deals @ $24M ARR (LIVE)
A3: ($mm) | B3: M1 | C3: M2 | D3: M3 | E3: M4 | F3: M5 | G3: M6 | H3: M7 | I3: M8 | J3: M9 | K3: M10 | L3: M11 | M3: M12 | N3: M13 | O3: M14 | P3: M15 | Q3: M16 | R3: M17 | S3: M18 | T3: M19 | U3: M20 | V3: M21 | W3: M22 | X3: M23 | Y3: M24 | Z3: M25 | AA3: M26 | AB3: M27 | AC3: M28 | AD3: M29 | AE3: M30 | AF3: M31 | AG3: M32 | AH3: M33 | AI3: M34 | AJ3: M35 | AK3: M36 | AL3: M37 | AM3: M38 | AN3: M39 | AO3: M40 | AP3: M41 | AQ3: M42 | AR3: M43 | AS3: M44 | AT3: M45 | AU3: M46 | AV3: M47 | AW3: M48 | AX3: M49 | AY3: M50 | AZ3: M51 | BA3: M52 | BB3: M53 | BC3: M54 | BD3: M55 | BE3: M56 | BF3: M57 | BG3: M58 | BH3: M59 | BI3: M60 | BJ3: M61 | BK3: M62 | BL3: M63 | BM3: M64 | BN3: M65 | BO3: M66 | BP3: M67 | BQ3: M68 | BR3: M69 | BS3: M70 | BT3: M71 | BU3: M72 | BV3: M73 | BW3: M74 | BX3: M75 | BY3: M76 | BZ3: M77 | CA3: M78 | CB3: M79 | CC3: M80 | CD3: M81 | CE3: M82 | CF3: M83 | CG3: M84 | CH3: M85 | CI3: M86 | CJ3: M87 | CK3: M88 | CL3: M89 | CM3: M90 | CN3: M91 | CO3: M92 | CP3: M93 | CQ3: M94 | CR3: M95 | CS3: M96 | CT3: M97 | CU3: M98 | CV3: M99 | CW3: M100 | CX3: M101 | CY3: M102 | CZ3: M103 | DA3: M104 | DB3: M105 | DC3: M106 | DD3: M107 | DE3: M108 | DF3: M109 | DG3: M110 | DH3: M111 | DI3: M112 | DJ3: M113 | DK3: M114 | DL3: M115 | DM3: M116 | DN3: M117 | DO3: M118 | DP3: M119 | DQ3: M120 | DR3: M121 | DS3: M122 | DT3: M123 | DU3: M124 | DV3: M125 | DW3: M126 | DX3: M127 | DY3: M128 | DZ3: M129 | EA3: M130 | EB3: M131 | EC3: M132 | ED3: M133 | EE3: M134 | EF3: M135 | EG3: M136 | EH3: M137 | EI3: M138 | EJ3: M139 | EK3: M140 | EL3: M141 | EM3: M142 | EN3: M143 | EO3: M144 | EP3: M145 | EQ3: M146 | ER3: M147 | ES3: M148 | ET3: M149 | EU3: M150 | EV3: M151 | EW3: M152 | EX3: M153 | EY3: M154 | EZ3: M155 | FA3: M156 | FB3: M157 | FC3: M158 | FD3: M159 | FE3: M160 | FF3: M161 | FG3: M162 | FH3: M163 | FI3: M164 | FJ3: M165 | FK3: M166 | FL3: M167 | FM3: M168 | FN3: M169 | FO3: M170 | FP3: M171 | FQ3: M172 | FR3: M173 | FS3: M174 | FT3: M175 | FU3: M176 | FV3: M177 | FW3: M178 | FX3: M179 | FY3: M180
A5: Revenue by Deal
A6: Deal #1 | B6: =_Engine_R50!F31/12 -> 0 | C6: =_Engine_R50!F32/12 -> 0 | D6: =_Engine_R50!F33/12 -> 0 | E6: =_Engine_R50!F34/12 -> 2.0833333 | F6: =_Engine_R50!F35/12 -> 2.0744473 | G6: =_Engine_R50!F36/12 -> 2.0655991 | H6: =_Engine_R50!F37/12 -> 2.0567886 | I6: =_Engine_R50!F38/12 -> 2.0480158 | J6: =_Engine_R50!F39/12 -> 2.0392803 | K6: =_Engine_R50!F40/12 -> 2.0305822 | L6: =_Engine_R50!F41/12 -> 2.0219211 | M6: =_Engine_R50!F42/12 -> 2.0132969 | N6: =_Engine_R50!F43/12 -> 2.0047096 | O6: =_Engine_R50!F44/12 -> 1.9961589 | P6: =_Engine_R50!F45/12 -> 1.9876446 | Q6: =_Engine_R50!F46/12 -> 1.9791667 | R6: =_Engine_R50!F47/12 -> 1.9707249 | S6: =_Engine_R50!F48/12 -> 1.9623191 | T6: =_Engine_R50!F49/12 -> 1.9539492 | U6: =_Engine_R50!F50/12 -> 1.945615 | V6: =_Engine_R50!F51/12 -> 1.9373163 | W6: =_Engine_R50!F52/12 -> 1.929053 | X6: =_Engine_R50!F53/12 -> 1.920825 | Y6: =_Engine_R50!F54/12 -> 1.9126321 | Z6: =_Engine_R50!F55/12 -> 1.9044741 | AA6: =_Engine_R50!F56/12 -> 1.8963509 | AB6: =_Engine_R50!F57/12 -> 1.8882624 | AC6: =_Engine_R50!F58/12 -> 1.8802083 | AD6: =_Engine_R50!F59/12 -> 1.8721886 | AE6: =_Engine_R50!F60/12 -> 1.8642032 | AF6: =_Engine_R50!F61/12 -> 1.8562517 | AG6: =_Engine_R50!F62/12 -> 1.8483342 | AH6: =_Engine_R50!F63/12 -> 1.8404505 | AI6: =_Engine_R50!F64/12 -> 1.8326004 | AJ6: =_Engine_R50!F65/12 -> 1.8247838 | AK6: =_Engine_R50!F66/12 -> 1.8170005 | AL6: =_Engine_R50!F67/12 -> 1.8092504 | AM6: =_Engine_R50!F68/12 -> 1.8015334 | AN6: =_Engine_R50!F69/12 -> 1.7938493 | AO6: =_Engine_R50!F70/12 -> 1.7861979 | AP6: =_Engine_R50!F71/12 -> 1.7785792 | AQ6: =_Engine_R50!F72/12 -> 1.770993 | AR6: =_Engine_R50!F73/12 -> 1.7634392 | AS6: =_Engine_R50!F74/12 -> 1.7559175 | AT6: =_Engine_R50!F75/12 -> 1.748428 | AU6: =_Engine_R50!F76/12 -> 1.7409704 | AV6: =_Engine_R50!F77/12 -> 1.7335446 | AW6: =_Engine_R50!F78/12 -> 1.7261505 | AX6: =_Engine_R50!F79/12 -> 1.7187879 | AY6: =_Engine_R50!F80/12 -> 1.7114567 | AZ6: =_Engine_R50!F81/12 -> 1.7041568 | BA6: =_Engine_R50!F82/12 -> 1.696888 | BB6: =_Engine_R50!F83/12 -> 1.6896503 | BC6: =_Engine_R50!F84/12 -> 1.6824434 | BD6: =_Engine_R50!F85/12 -> 1.6752672 | BE6: =_Engine_R50!F86/12 -> 1.6681216 | BF6: =_Engine_R50!F87/12 -> 1.6610066 | BG6: =_Engine_R50!F88/12 -> 1.6539219 | BH6: =_Engine_R50!F89/12 -> 1.6468674 | BI6: =_Engine_R50!F90/12 -> 1.6398429 | BJ6: =_Engine_R50!F91/12 -> 1.6328485 | BK6: =_Engine_R50!F92/12 -> 1.6258839 | BL6: =_Engine_R50!F93/12 -> 1.618949 | BM6: =_Engine_R50!F94/12 -> 1.6120436 | BN6: =_Engine_R50!F95/12 -> 1.6051677 | BO6: =_Engine_R50!F96/12 -> 1.5983212 | BP6: =_Engine_R50!F97/12 -> 1.5915038 | BQ6: =_Engine_R50!F98/12 -> 1.5847156 | BR6: =_Engine_R50!F99/12 -> 1.5779563 | BS6: =_Engine_R50!F100/12 -> 1.5712258 | BT6: =_Engine_R50!F101/12 -> 1.564524 | BU6: =_Engine_R50!F102/12 -> 1.5578508 | BV6: =_Engine_R50!F103/12 -> 1.5512061 | BW6: =_Engine_R50!F104/12 -> 1.5445897 | BX6: =_Engine_R50!F105/12 -> 1.5380015 | BY6: =_Engine_R50!F106/12 -> 1.5314414 | BZ6: =_Engine_R50!F107/12 -> 1.5249094 | CA6: =_Engine_R50!F108/12 -> 1.5184051 | CB6: =_Engine_R50!F109/12 -> 1.5119286 | CC6: =_Engine_R50!F110/12 -> 1.5054798 | CD6: =_Engine_R50!F111/12 -> 1.4990584 | CE6: =_Engine_R50!F112/12 -> 1.4926645 | CF6: =_Engine_R50!F113/12 -> 1.4862978 | CG6: =_Engine_R50!F114/12 -> 1.4799583 | CH6: =_Engine_R50!F115/12 -> 1.4736458 | CI6: =_Engine_R50!F116/12 -> 1.4673602 | CJ6: =_Engine_R50!F117/12 -> 1.4611014 | CK6: =_Engine_R50!F118/12 -> 1.4548694 | CL6: =_Engine_R50!F119/12 -> 1.4486639 | CM6: =_Engine_R50!F120/12 -> 1.4424849 | CN6: =_Engine_R50!F121/12 -> 1.4363322 | CO6: =_Engine_R50!F122/12 -> 1.4302058 | CP6: =_Engine_R50!F123/12 -> 1.4241055 | CQ6: =_Engine_R50!F124/12 -> 1.4180313 | CR6: =_Engine_R50!F125/12 -> 1.4119829 | CS6: =_Engine_R50!F126/12 -> 1.4059603 | CT6: =_Engine_R50!F127/12 -> 1.3999635 | CU6: =_Engine_R50!F128/12 -> 1.3939922 | CV6: =_Engine_R50!F129/12 -> 1.3880464 | CW6: =_Engine_R50!F130/12 -> 1.3821259 | CX6: =_Engine_R50!F131/12 -> 1.3762307 | CY6: =_Engine_R50!F132/12 -> 1.3703606 | CZ6: =_Engine_R50!F133/12 -> 1.3645156 | DA6: =_Engine_R50!F134/12 -> 1.3586955 | DB6: =_Engine_R50!F135/12 -> 1.3529002 | DC6: =_Engine_R50!F136/12 -> 1.3471297 | DD6: =_Engine_R50!F137/12 -> 1.3413838 | DE6: =_Engine_R50!F138/12 -> 1.3356623 | DF6: =_Engine_R50!F139/12 -> 1.3299653 | DG6: =_Engine_R50!F140/12 -> 1.3242926 | DH6: =_Engine_R50!F141/12 -> 1.318644 | DI6: =_Engine_R50!F142/12 -> 1.3130196 | DJ6: =_Engine_R50!F143/12 -> 1.3074192 | DK6: =_Engine_R50!F144/12 -> 1.3018426 | DL6: =_Engine_R50!F145/12 -> 1.2962898 | DM6: =_Engine_R50!F146/12 -> 1.2907607 | DN6: =_Engine_R50!F147/12 -> 1.2852552 | DO6: =_Engine_R50!F148/12 -> 1.2797732 | DP6: =_Engine_R50!F149/12 -> 1.2743146 | DQ6: =_Engine_R50!F150/12 -> 1.2688792 | DR6: =_Engine_R50!F151/12 -> 1.263467 | DS6: =_Engine_R50!F152/12 -> 1.2580779 | DT6: =_Engine_R50!F153/12 -> 1.2527118 | DU6: =_Engine_R50!F154/12 -> 1.2473686 | DV6: =_Engine_R50!F155/12 -> 1.2420482 | DW6: =_Engine_R50!F156/12 -> 1.2367505 | DX6: =_Engine_R50!F157/12 -> 1.2314753 | DY6: =_Engine_R50!F158/12 -> 1.2262227 | DZ6: =_Engine_R50!F159/12 -> 1.2209925 | EA6: =_Engine_R50!F160/12 -> 1.2157845 | EB6: =_Engine_R50!F161/12 -> 1.2105988 | EC6: =_Engine_R50!F162/12 -> 1.2054352 | ED6: =_Engine_R50!F163/12 -> 1.2002937 | EE6: =_Engine_R50!F164/12 -> 1.195174 | EF6: =_Engine_R50!F165/12 -> 1.1900762 | EG6: =_Engine_R50!F166/12 -> 1.1850002 | EH6: =_Engine_R50!F167/12 -> 1.1799458 | EI6: =_Engine_R50!F168/12 -> 1.1749129 | EJ6: =_Engine_R50!F169/12 -> 1.1699016 | EK6: =_Engine_R50!F170/12 -> 1.1649116 | EL6: =_Engine_R50!F171/12 -> 1.1599428 | EM6: =_Engine_R50!F172/12 -> 1.1549953 | EN6: =_Engine_R50!F173/12 -> 1.1500689 | EO6: =_Engine_R50!F174/12 -> 1.1451635 | EP6: =_Engine_R50!F175/12 -> 1.140279 | EQ6: =_Engine_R50!F176/12 -> 1.1354153 | ER6: =_Engine_R50!F177/12 -> 1.1305724 | ES6: =_Engine_R50!F178/12 -> 1.1257502 | ET6: =_Engine_R50!F179/12 -> 1.1209485 | EU6: =_Engine_R50!F180/12 -> 1.1161673 | EV6: =_Engine_R50!F181/12 -> 1.1114065 | EW6: =_Engine_R50!F182/12 -> 1.106666 | EX6: =_Engine_R50!F183/12 -> 1.1019457 | EY6: =_Engine_R50!F184/12 -> 1.0972456 | EZ6: =_Engine_R50!F185/12 -> 1.0925654 | FA6: =_Engine_R50!F186/12 -> 1.0879053 | FB6: =_Engine_R50!F187/12 -> 1.083265 | FC6: =_Engine_R50!F188/12 -> 1.0786446 | FD6: =_Engine_R50!F189/12 -> 1.0740438 | FE6: =_Engine_R50!F190/12 -> 1.0694627 | FF6: =_Engine_R50!F191/12 -> 1.0649011 | FG6: =_Engine_R50!F192/12 -> 1.0603589 | FH6: =_Engine_R50!F193/12 -> 1.0558362 | FI6: =_Engine_R50!F194/12 -> 1.0513327 | FJ6: =_Engine_R50!F195/12 -> 1.0468484 | FK6: =_Engine_R50!F196/12 -> 1.0423833 | FL6: =_Engine_R50!F197/12 -> 1.0379372 | FM6: =_Engine_R50!F198/12 -> 1.03351 | FN6: =_Engine_R50!F199/12 -> 1.0291018 | FO6: =_Engine_R50!F200/12 -> 1.0247123 | FP6: =_Engine_R50!F201/12 -> 1.0203416 | FQ6: =_Engine_R50!F202/12 -> 1.0159895 | FR6: =_Engine_R50!F203/12 -> 1.011656 | FS6: =_Engine_R50!F204/12 -> 1.007341 | FT6: =_Engine_R50!F205/12 -> 1.0030444 | FU6: =_Engine_R50!F206/12 -> 0.99876605 | FV6: =_Engine_R50!F207/12 -> 0.994506 | FW6: =_Engine_R50!F208/12 -> 0.99026411 | FX6: =_Engine_R50!F209/12 -> 0.98604032 | FY6: =_Engine_R50!F210/12 -> 0.98183454
A7: Deal #2 | B7: =_Engine_R50!G31/12 -> 0 | C7: =_Engine_R50!G32/12 -> 0 | D7: =_Engine_R50!G33/12 -> 0 | E7: =_Engine_R50!G34/12 -> 0 | F7: =_Engine_R50!G35/12 -> 0 | G7: =_Engine_R50!G36/12 -> 0 | H7: =_Engine_R50!G37/12 -> 0 | I7: =_Engine_R50!G38/12 -> 2.0833333 | J7: =_Engine_R50!G39/12 -> 2.0651216 | K7: =_Engine_R50!G40/12 -> 2.0470692 | L7: =_Engine_R50!G41/12 -> 2.0291745 | M7: =_Engine_R50!G42/12 -> 2.0114362 | N7: =_Engine_R50!G43/12 -> 1.993853 | O7: =_Engine_R50!G44/12 -> 1.9764235 | P7: =_Engine_R50!G45/12 -> 1.9591464 | Q7: =_Engine_R50!G46/12 -> 1.9420203 | R7: =_Engine_R50!G47/12 -> 1.9250439 | S7: =_Engine_R50!G48/12 -> 1.9082159 | T7: =_Engine_R50!G49/12 -> 1.8915351 | U7: =_Engine_R50!G50/12 -> 1.875 | V7: =_Engine_R50!G51/12 -> 1.8586095 | W7: =_Engine_R50!G52/12 -> 1.8423622 | X7: =_Engine_R50!G53/12 -> 1.826257 | Y7: =_Engine_R50!G54/12 -> 1.8102926 | Z7: =_Engine_R50!G55/12 -> 1.7944677 | AA7: =_Engine_R50!G56/12 -> 1.7787812 | AB7: =_Engine_R50!G57/12 -> 1.7632318 | AC7: =_Engine_R50!G58/12 -> 1.7478183 | AD7: =_Engine_R50!G59/12 -> 1.7325395 | AE7: =_Engine_R50!G60/12 -> 1.7173944 | AF7: =_Engine_R50!G61/12 -> 1.7023816 | AG7: =_Engine_R50!G62/12 -> 1.6875 | AH7: =_Engine_R50!G63/12 -> 1.6727485 | AI7: =_Engine_R50!G64/12 -> 1.658126 | AJ7: =_Engine_R50!G65/12 -> 1.6436313 | AK7: =_Engine_R50!G66/12 -> 1.6292633 | AL7: =_Engine_R50!G67/12 -> 1.615021 | AM7: =_Engine_R50!G68/12 -> 1.6009031 | AN7: =_Engine_R50!G69/12 -> 1.5869086 | AO7: =_Engine_R50!G70/12 -> 1.5730365 | AP7: =_Engine_R50!G71/12 -> 1.5592856 | AQ7: =_Engine_R50!G72/12 -> 1.5456549 | AR7: =_Engine_R50!G73/12 -> 1.5321434 | AS7: =_Engine_R50!G74/12 -> 1.51875 | AT7: =_Engine_R50!G75/12 -> 1.5054737 | AU7: =_Engine_R50!G76/12 -> 1.4923134 | AV7: =_Engine_R50!G77/12 -> 1.4792682 | AW7: =_Engine_R50!G78/12 -> 1.466337 | AX7: =_Engine_R50!G79/12 -> 1.4535189 | AY7: =_Engine_R50!G80/12 -> 1.4408128 | AZ7: =_Engine_R50!G81/12 -> 1.4282177 | BA7: =_Engine_R50!G82/12 -> 1.4157328 | BB7: =_Engine_R50!G83/12 -> 1.403357 | BC7: =_Engine_R50!G84/12 -> 1.3910894 | BD7: =_Engine_R50!G85/12 -> 1.3789291 | BE7: =_Engine_R50!G86/12 -> 1.366875 | BF7: =_Engine_R50!G87/12 -> 1.3549263 | BG7: =_Engine_R50!G88/12 -> 1.3430821 | BH7: =_Engine_R50!G89/12 -> 1.3313414 | BI7: =_Engine_R50!G90/12 -> 1.3197033 | BJ7: =_Engine_R50!G91/12 -> 1.308167 | BK7: =_Engine_R50!G92/12 -> 1.2967315 | BL7: =_Engine_R50!G93/12 -> 1.285396 | BM7: =_Engine_R50!G94/12 -> 1.2741595 | BN7: =_Engine_R50!G95/12 -> 1.2630213 | BO7: =_Engine_R50!G96/12 -> 1.2519805 | BP7: =_Engine_R50!G97/12 -> 1.2410362 | BQ7: =_Engine_R50!G98/12 -> 1.2301875 | BR7: =_Engine_R50!G99/12 -> 1.2194337 | BS7: =_Engine_R50!G100/12 -> 1.2087739 | BT7: =_Engine_R50!G101/12 -> 1.1982072 | BU7: =_Engine_R50!G102/12 -> 1.187733 | BV7: =_Engine_R50!G103/12 -> 1.1773503 | BW7: =_Engine_R50!G104/12 -> 1.1670583 | BX7: =_Engine_R50!G105/12 -> 1.1568564 | BY7: =_Engine_R50!G106/12 -> 1.1467436 | BZ7: =_Engine_R50!G107/12 -> 1.1367192 | CA7: =_Engine_R50!G108/12 -> 1.1267824 | CB7: =_Engine_R50!G109/12 -> 1.1169325 | CC7: =_Engine_R50!G110/12 -> 1.1071688 | CD7: =_Engine_R50!G111/12 -> 1.0974903 | CE7: =_Engine_R50!G112/12 -> 1.0878965 | CF7: =_Engine_R50!G113/12 -> 1.0783865 | CG7: =_Engine_R50!G114/12 -> 1.0689597 | CH7: =_Engine_R50!G115/12 -> 1.0596152 | CI7: =_Engine_R50!G116/12 -> 1.0503525 | CJ7: =_Engine_R50!G117/12 -> 1.0411707 | CK7: =_Engine_R50!G118/12 -> 1.0320692 | CL7: =_Engine_R50!G119/12 -> 1.0230473 | CM7: =_Engine_R50!G120/12 -> 1.0141042 | CN7: =_Engine_R50!G121/12 -> 1.0052393 | CO7: =_Engine_R50!G122/12 -> 0.99645187 | CP7: =_Engine_R50!G123/12 -> 0.98774128 | CQ7: =_Engine_R50!G124/12 -> 0.97910683 | CR7: =_Engine_R50!G125/12 -> 0.97054786 | CS7: =_Engine_R50!G126/12 -> 0.96206371 | CT7: =_Engine_R50!G127/12 -> 0.95365372 | CU7: =_Engine_R50!G128/12 -> 0.94531725 | CV7: =_Engine_R50!G129/12 -> 0.93705366 | CW7: =_Engine_R50!G130/12 -> 0.9288623 | CX7: =_Engine_R50!G131/12 -> 0.92074254 | CY7: =_Engine_R50!G132/12 -> 0.91269377 | CZ7: =_Engine_R50!G133/12 -> 0.90471536 | DA7: =_Engine_R50!G134/12 -> 0.89680669 | DB7: =_Engine_R50!G135/12 -> 0.88896715 | DC7: =_Engine_R50!G136/12 -> 0.88119615 | DD7: =_Engine_R50!G137/12 -> 0.87349307 | DE7: =_Engine_R50!G138/12 -> 0.86585734 | DF7: =_Engine_R50!G139/12 -> 0.85828835 | DG7: =_Engine_R50!G140/12 -> 0.85078553 | DH7: =_Engine_R50!G141/12 -> 0.84334829 | DI7: =_Engine_R50!G142/12 -> 0.83597607 | DJ7: =_Engine_R50!G143/12 -> 0.82866829 | DK7: =_Engine_R50!G144/12 -> 0.82142439 | DL7: =_Engine_R50!G145/12 -> 0.81424382 | DM7: =_Engine_R50!G146/12 -> 0.80712602 | DN7: =_Engine_R50!G147/12 -> 0.80007044 | DO7: =_Engine_R50!G148/12 -> 0.79307653 | DP7: =_Engine_R50!G149/12 -> 0.78614377 | DQ7: =_Engine_R50!G150/12 -> 0.7792716 | DR7: =_Engine_R50!G151/12 -> 0.77245951 | DS7: =_Engine_R50!G152/12 -> 0.76570697 | DT7: =_Engine_R50!G153/12 -> 0.75901346 | DU7: =_Engine_R50!G154/12 -> 0.75237846 | DV7: =_Engine_R50!G155/12 -> 0.74580146 | DW7: =_Engine_R50!G156/12 -> 0.73928195 | DX7: =_Engine_R50!G157/12 -> 0.73281944 | DY7: =_Engine_R50!G158/12 -> 0.72641342 | DZ7: =_Engine_R50!G159/12 -> 0.72006339 | EA7: =_Engine_R50!G160/12 -> 0.71376888 | EB7: =_Engine_R50!G161/12 -> 0.70752939 | EC7: =_Engine_R50!G162/12 -> 0.70134444 | ED7: =_Engine_R50!G163/12 -> 0.69521356 | EE7: =_Engine_R50!G164/12 -> 0.68913628 | EF7: =_Engine_R50!G165/12 -> 0.68311211 | EG7: =_Engine_R50!G166/12 -> 0.67714061 | EH7: =_Engine_R50!G167/12 -> 0.67122131 | EI7: =_Engine_R50!G168/12 -> 0.66535376 | EJ7: =_Engine_R50!G169/12 -> 0.6595375 | EK7: =_Engine_R50!G170/12 -> 0.65377208 | EL7: =_Engine_R50!G171/12 -> 0.64805705 | EM7: =_Engine_R50!G172/12 -> 0.64239199 | EN7: =_Engine_R50!G173/12 -> 0.63677645 | EO7: =_Engine_R50!G174/12 -> 0.63121 | EP7: =_Engine_R50!G175/12 -> 0.62569221 | EQ7: =_Engine_R50!G176/12 -> 0.62022265 | ER7: =_Engine_R50!G177/12 -> 0.6148009 | ES7: =_Engine_R50!G178/12 -> 0.60942655 | ET7: =_Engine_R50!G179/12 -> 0.60409918 | EU7: =_Engine_R50!G180/12 -> 0.59881838 | EV7: =_Engine_R50!G181/12 -> 0.59358375 | EW7: =_Engine_R50!G182/12 -> 0.58839487 | EX7: =_Engine_R50!G183/12 -> 0.58325135 | EY7: =_Engine_R50!G184/12 -> 0.57815279 | EZ7: =_Engine_R50!G185/12 -> 0.57309881 | FA7: =_Engine_R50!G186/12 -> 0.568089 | FB7: =_Engine_R50!G187/12 -> 0.56312299 | FC7: =_Engine_R50!G188/12 -> 0.55820038 | FD7: =_Engine_R50!G189/12 -> 0.55332081 | FE7: =_Engine_R50!G190/12 -> 0.5484839 | FF7: =_Engine_R50!G191/12 -> 0.54368926 | FG7: =_Engine_R50!G192/12 -> 0.53893654 | FH7: =_Engine_R50!G193/12 -> 0.53422537 | FI7: =_Engine_R50!G194/12 -> 0.52955538 | FJ7: =_Engine_R50!G195/12 -> 0.52492621 | FK7: =_Engine_R50!G196/12 -> 0.52033751 | FL7: =_Engine_R50!G197/12 -> 0.51578892 | FM7: =_Engine_R50!G198/12 -> 0.5112801 | FN7: =_Engine_R50!G199/12 -> 0.50681069 | FO7: =_Engine_R50!G200/12 -> 0.50238035 | FP7: =_Engine_R50!G201/12 -> 0.49798873 | FQ7: =_Engine_R50!G202/12 -> 0.49363551 | FR7: =_Engine_R50!G203/12 -> 0.48932034 | FS7: =_Engine_R50!G204/12 -> 0.48504289 | FT7: =_Engine_R50!G205/12 -> 0.48080283 | FU7: =_Engine_R50!G206/12 -> 0.47659984 | FV7: =_Engine_R50!G207/12 -> 0.47243359 | FW7: =_Engine_R50!G208/12 -> 0.46830376 | FX7: =_Engine_R50!G209/12 -> 0.46421003 | FY7: =_Engine_R50!G210/12 -> 0.46015209
A8: Deal #3 | B8: =_Engine_R50!H31/12 -> 0 | C8: =_Engine_R50!H32/12 -> 0 | D8: =_Engine_R50!H33/12 -> 0 | E8: =_Engine_R50!H34/12 -> 0 | F8: =_Engine_R50!H35/12 -> 0 | G8: =_Engine_R50!H36/12 -> 0 | H8: =_Engine_R50!H37/12 -> 0 | I8: =_Engine_R50!H38/12 -> 0 | J8: =_Engine_R50!H39/12 -> 0 | K8: =_Engine_R50!H40/12 -> 0 | L8: =_Engine_R50!H41/12 -> 0 | M8: =_Engine_R50!H42/12 -> 2.0833333 | N8: =_Engine_R50!H43/12 -> 2.0553084 | O8: =_Engine_R50!H44/12 -> 2.0276605 | P8: =_Engine_R50!H45/12 -> 2.0003846 | Q8: =_Engine_R50!H46/12 -> 1.9734755 | R8: =_Engine_R50!H47/12 -> 1.9469284 | S8: =_Engine_R50!H48/12 -> 1.9207384 | T8: =_Engine_R50!H49/12 -> 1.8949008 | U8: =_Engine_R50!H50/12 -> 1.8694107 | V8: =_Engine_R50!H51/12 -> 1.8442634 | W8: =_Engine_R50!H52/12 -> 1.8194545 | X8: =_Engine_R50!H53/12 -> 1.7949793 | Y8: =_Engine_R50!H54/12 -> 1.7708333 | Z8: =_Engine_R50!H55/12 -> 1.7470122 | AA8: =_Engine_R50!H56/12 -> 1.7235115 | AB8: =_Engine_R50!H57/12 -> 1.7003269 | AC8: =_Engine_R50!H58/12 -> 1.6774542 | AD8: =_Engine_R50!H59/12 -> 1.6548891 | AE8: =_Engine_R50!H60/12 -> 1.6326277 | AF8: =_Engine_R50!H61/12 -> 1.6106656 | AG8: =_Engine_R50!H62/12 -> 1.5889991 | AH8: =_Engine_R50!H63/12 -> 1.5676239 | AI8: =_Engine_R50!H64/12 -> 1.5465363 | AJ8: =_Engine_R50!H65/12 -> 1.5257324 | AK8: =_Engine_R50!H66/12 -> 1.5052083 | AL8: =_Engine_R50!H67/12 -> 1.4849604 | AM8: =_Engine_R50!H68/12 -> 1.4649847 | AN8: =_Engine_R50!H69/12 -> 1.4452778 | AO8: =_Engine_R50!H70/12 -> 1.425836 | AP8: =_Engine_R50!H71/12 -> 1.4066558 | AQ8: =_Engine_R50!H72/12 -> 1.3877335 | AR8: =_Engine_R50!H73/12 -> 1.3690658 | AS8: =_Engine_R50!H74/12 -> 1.3506492 | AT8: =_Engine_R50!H75/12 -> 1.3324803 | AU8: =_Engine_R50!H76/12 -> 1.3145559 | AV8: =_Engine_R50!H77/12 -> 1.2968725 | AW8: =_Engine_R50!H78/12 -> 1.2794271 | AX8: =_Engine_R50!H79/12 -> 1.2622163 | AY8: =_Engine_R50!H80/12 -> 1.245237 | AZ8: =_Engine_R50!H81/12 -> 1.2284862 | BA8: =_Engine_R50!H82/12 -> 1.2119606 | BB8: =_Engine_R50!H83/12 -> 1.1956574 | BC8: =_Engine_R50!H84/12 -> 1.1795735 | BD8: =_Engine_R50!H85/12 -> 1.1637059 | BE8: =_Engine_R50!H86/12 -> 1.1480518 | BF8: =_Engine_R50!H87/12 -> 1.1326083 | BG8: =_Engine_R50!H88/12 -> 1.1173725 | BH8: =_Engine_R50!H89/12 -> 1.1023417 | BI8: =_Engine_R50!H90/12 -> 1.087513 | BJ8: =_Engine_R50!H91/12 -> 1.0728839 | BK8: =_Engine_R50!H92/12 -> 1.0584515 | BL8: =_Engine_R50!H93/12 -> 1.0442132 | BM8: =_Engine_R50!H94/12 -> 1.0301665 | BN8: =_Engine_R50!H95/12 -> 1.0163088 | BO8: =_Engine_R50!H96/12 -> 1.0026375 | BP8: =_Engine_R50!H97/12 -> 0.98915004 | BQ8: =_Engine_R50!H98/12 -> 0.97584404 | BR8: =_Engine_R50!H99/12 -> 0.96271704 | BS8: =_Engine_R50!H100/12 -> 0.94976662 | BT8: =_Engine_R50!H101/12 -> 0.93699041 | BU8: =_Engine_R50!H102/12 -> 0.92438607 | BV8: =_Engine_R50!H103/12 -> 0.91195128 | BW8: =_Engine_R50!H104/12 -> 0.89968376 | BX8: =_Engine_R50!H105/12 -> 0.88758126 | BY8: =_Engine_R50!H106/12 -> 0.87564156 | BZ8: =_Engine_R50!H107/12 -> 0.86386248 | CA8: =_Engine_R50!H108/12 -> 0.85224184 | CB8: =_Engine_R50!H109/12 -> 0.84077753 | CC8: =_Engine_R50!H110/12 -> 0.82946744 | CD8: =_Engine_R50!H111/12 -> 0.81830949 | CE8: =_Engine_R50!H112/12 -> 0.80730163 | CF8: =_Engine_R50!H113/12 -> 0.79644185 | CG8: =_Engine_R50!H114/12 -> 0.78572816 | CH8: =_Engine_R50!H115/12 -> 0.77515858 | CI8: =_Engine_R50!H116/12 -> 0.76473119 | CJ8: =_Engine_R50!H117/12 -> 0.75444407 | CK8: =_Engine_R50!H118/12 -> 0.74429533 | CL8: =_Engine_R50!H119/12 -> 0.73428311 | CM8: =_Engine_R50!H120/12 -> 0.72440557 | CN8: =_Engine_R50!H121/12 -> 0.7146609 | CO8: =_Engine_R50!H122/12 -> 0.70504732 | CP8: =_Engine_R50!H123/12 -> 0.69556306 | CQ8: =_Engine_R50!H124/12 -> 0.68620639 | CR8: =_Engine_R50!H125/12 -> 0.67697557 | CS8: =_Engine_R50!H126/12 -> 0.66786893 | CT8: =_Engine_R50!H127/12 -> 0.6588848 | CU8: =_Engine_R50!H128/12 -> 0.65002151 | CV8: =_Engine_R50!H129/12 -> 0.64127746 | CW8: =_Engine_R50!H130/12 -> 0.63265103 | CX8: =_Engine_R50!H131/12 -> 0.62414064 | CY8: =_Engine_R50!H132/12 -> 0.61574473 | CZ8: =_Engine_R50!H133/12 -> 0.60746177 | DA8: =_Engine_R50!H134/12 -> 0.59929022 | DB8: =_Engine_R50!H135/12 -> 0.5912286 | DC8: =_Engine_R50!H136/12 -> 0.58327543 | DD8: =_Engine_R50!H137/12 -> 0.57542924 | DE8: =_Engine_R50!H138/12 -> 0.56768859 | DF8: =_Engine_R50!H139/12 -> 0.56005208 | DG8: =_Engine_R50!H140/12 -> 0.55251829 | DH8: =_Engine_R50!H141/12 -> 0.54508584 | DI8: =_Engine_R50!H142/12 -> 0.53775337 | DJ8: =_Engine_R50!H143/12 -> 0.53051954 | DK8: =_Engine_R50!H144/12 -> 0.52338302 | DL8: =_Engine_R50!H145/12 -> 0.5163425 | DM8: =_Engine_R50!H146/12 -> 0.50939669 | DN8: =_Engine_R50!H147/12 -> 0.50254431 | DO8: =_Engine_R50!H148/12 -> 0.49578411 | DP8: =_Engine_R50!H149/12 -> 0.48911485 | DQ8: =_Engine_R50!H150/12 -> 0.4825353 | DR8: =_Engine_R50!H151/12 -> 0.47604427 | DS8: =_Engine_R50!H152/12 -> 0.46964054 | DT8: =_Engine_R50!H153/12 -> 0.46332296 | DU8: =_Engine_R50!H154/12 -> 0.45709037 | DV8: =_Engine_R50!H155/12 -> 0.45094161 | DW8: =_Engine_R50!H156/12 -> 0.44487557 | DX8: =_Engine_R50!H157/12 -> 0.43889113 | DY8: =_Engine_R50!H158/12 -> 0.43298719 | DZ8: =_Engine_R50!H159/12 -> 0.42716267 | EA8: =_Engine_R50!H160/12 -> 0.4214165 | EB8: =_Engine_R50!H161/12 -> 0.41574762 | EC8: =_Engine_R50!H162/12 -> 0.41015501 | ED8: =_Engine_R50!H163/12 -> 0.40463763 | EE8: =_Engine_R50!H164/12 -> 0.39919446 | EF8: =_Engine_R50!H165/12 -> 0.39382452 | EG8: =_Engine_R50!H166/12 -> 0.38852681 | EH8: =_Engine_R50!H167/12 -> 0.38330037 | EI8: =_Engine_R50!H168/12 -> 0.37814423 | EJ8: =_Engine_R50!H169/12 -> 0.37305746 | EK8: =_Engine_R50!H170/12 -> 0.36803911 | EL8: =_Engine_R50!H171/12 -> 0.36308827 | EM8: =_Engine_R50!H172/12 -> 0.35820402 | EN8: =_Engine_R50!H173/12 -> 0.35338548 | EO8: =_Engine_R50!H174/12 -> 0.34863176 | EP8: =_Engine_R50!H175/12 -> 0.34394198 | EQ8: =_Engine_R50!H176/12 -> 0.33931529 | ER8: =_Engine_R50!H177/12 -> 0.33475084 | ES8: =_Engine_R50!H178/12 -> 0.33024779 | ET8: =_Engine_R50!H179/12 -> 0.32580531 | EU8: =_Engine_R50!H180/12 -> 0.3214226 | EV8: =_Engine_R50!H181/12 -> 0.31709884 | EW8: =_Engine_R50!H182/12 -> 0.31283324 | EX8: =_Engine_R50!H183/12 -> 0.30862503 | EY8: =_Engine_R50!H184/12 -> 0.30447342 | EZ8: =_Engine_R50!H185/12 -> 0.30037766 | FA8: =_Engine_R50!H186/12 -> 0.29633699 | FB8: =_Engine_R50!H187/12 -> 0.29235068 | FC8: =_Engine_R50!H188/12 -> 0.288418 | FD8: =_Engine_R50!H189/12 -> 0.28453821 | FE8: =_Engine_R50!H190/12 -> 0.28071062 | FF8: =_Engine_R50!H191/12 -> 0.27693452 | FG8: =_Engine_R50!H192/12 -> 0.27320921 | FH8: =_Engine_R50!H193/12 -> 0.26953401 | FI8: =_Engine_R50!H194/12 -> 0.26590826 | FJ8: =_Engine_R50!H195/12 -> 0.26233127 | FK8: =_Engine_R50!H196/12 -> 0.25880241 | FL8: =_Engine_R50!H197/12 -> 0.25532101 | FM8: =_Engine_R50!H198/12 -> 0.25188644 | FN8: =_Engine_R50!H199/12 -> 0.24849808 | FO8: =_Engine_R50!H200/12 -> 0.2451553 | FP8: =_Engine_R50!H201/12 -> 0.24185748 | FQ8: =_Engine_R50!H202/12 -> 0.23860403 | FR8: =_Engine_R50!H203/12 -> 0.23539434 | FS8: =_Engine_R50!H204/12 -> 0.23222783 | FT8: =_Engine_R50!H205/12 -> 0.22910391 | FU8: =_Engine_R50!H206/12 -> 0.22602202 | FV8: =_Engine_R50!H207/12 -> 0.22298158 | FW8: =_Engine_R50!H208/12 -> 0.21998204 | FX8: =_Engine_R50!H209/12 -> 0.21702286 | FY8: =_Engine_R50!H210/12 -> 0.21410348
A9: Deal #4 | B9: =_Engine_R50!I31/12 -> 0 | C9: =_Engine_R50!I32/12 -> 0 | D9: =_Engine_R50!I33/12 -> 0 | E9: =_Engine_R50!I34/12 -> 0 | F9: =_Engine_R50!I35/12 -> 0 | G9: =_Engine_R50!I36/12 -> 0 | H9: =_Engine_R50!I37/12 -> 0 | I9: =_Engine_R50!I38/12 -> 0 | J9: =_Engine_R50!I39/12 -> 0 | K9: =_Engine_R50!I40/12 -> 0 | L9: =_Engine_R50!I41/12 -> 0 | M9: =_Engine_R50!I42/12 -> 0 | N9: =_Engine_R50!I43/12 -> 0 | O9: =_Engine_R50!I44/12 -> 0 | P9: =_Engine_R50!I45/12 -> 0 | Q9: =_Engine_R50!I46/12 -> 2.0833333 | R9: =_Engine_R50!I47/12 -> 2.0553084 | S9: =_Engine_R50!I48/12 -> 2.0276605 | T9: =_Engine_R50!I49/12 -> 2.0003846 | U9: =_Engine_R50!I50/12 -> 1.9734755 | V9: =_Engine_R50!I51/12 -> 1.9469284 | W9: =_Engine_R50!I52/12 -> 1.9207384 | X9: =_Engine_R50!I53/12 -> 1.8949008 | Y9: =_Engine_R50!I54/12 -> 1.8694107 | Z9: =_Engine_R50!I55/12 -> 1.8442634 | AA9: =_Engine_R50!I56/12 -> 1.8194545 | AB9: =_Engine_R50!I57/12 -> 1.7949793 | AC9: =_Engine_R50!I58/12 -> 1.7708333 | AD9: =_Engine_R50!I59/12 -> 1.7470122 | AE9: =_Engine_R50!I60/12 -> 1.7235115 | AF9: =_Engine_R50!I61/12 -> 1.7003269 | AG9: =_Engine_R50!I62/12 -> 1.6774542 | AH9: =_Engine_R50!I63/12 -> 1.6548891 | AI9: =_Engine_R50!I64/12 -> 1.6326277 | AJ9: =_Engine_R50!I65/12 -> 1.6106656 | AK9: =_Engine_R50!I66/12 -> 1.5889991 | AL9: =_Engine_R50!I67/12 -> 1.5676239 | AM9: =_Engine_R50!I68/12 -> 1.5465363 | AN9: =_Engine_R50!I69/12 -> 1.5257324 | AO9: =_Engine_R50!I70/12 -> 1.5052083 | AP9: =_Engine_R50!I71/12 -> 1.4849604 | AQ9: =_Engine_R50!I72/12 -> 1.4649847 | AR9: =_Engine_R50!I73/12 -> 1.4452778 | AS9: =_Engine_R50!I74/12 -> 1.425836 | AT9: =_Engine_R50!I75/12 -> 1.4066558 | AU9: =_Engine_R50!I76/12 -> 1.3877335 | AV9: =_Engine_R50!I77/12 -> 1.3690658 | AW9: =_Engine_R50!I78/12 -> 1.3506492 | AX9: =_Engine_R50!I79/12 -> 1.3324803 | AY9: =_Engine_R50!I80/12 -> 1.3145559 | AZ9: =_Engine_R50!I81/12 -> 1.2968725 | BA9: =_Engine_R50!I82/12 -> 1.2794271 | BB9: =_Engine_R50!I83/12 -> 1.2622163 | BC9: =_Engine_R50!I84/12 -> 1.245237 | BD9: =_Engine_R50!I85/12 -> 1.2284862 | BE9: =_Engine_R50!I86/12 -> 1.2119606 | BF9: =_Engine_R50!I87/12 -> 1.1956574 | BG9: =_Engine_R50!I88/12 -> 1.1795735 | BH9: =_Engine_R50!I89/12 -> 1.1637059 | BI9: =_Engine_R50!I90/12 -> 1.1480518 | BJ9: =_Engine_R50!I91/12 -> 1.1326083 | BK9: =_Engine_R50!I92/12 -> 1.1173725 | BL9: =_Engine_R50!I93/12 -> 1.1023417 | BM9: =_Engine_R50!I94/12 -> 1.087513 | BN9: =_Engine_R50!I95/12 -> 1.0728839 | BO9: =_Engine_R50!I96/12 -> 1.0584515 | BP9: =_Engine_R50!I97/12 -> 1.0442132 | BQ9: =_Engine_R50!I98/12 -> 1.0301665 | BR9: =_Engine_R50!I99/12 -> 1.0163088 | BS9: =_Engine_R50!I100/12 -> 1.0026375 | BT9: =_Engine_R50!I101/12 -> 0.98915004 | BU9: =_Engine_R50!I102/12 -> 0.97584404 | BV9: =_Engine_R50!I103/12 -> 0.96271704 | BW9: =_Engine_R50!I104/12 -> 0.94976662 | BX9: =_Engine_R50!I105/12 -> 0.93699041 | BY9: =_Engine_R50!I106/12 -> 0.92438607 | BZ9: =_Engine_R50!I107/12 -> 0.91195128 | CA9: =_Engine_R50!I108/12 -> 0.89968376 | CB9: =_Engine_R50!I109/12 -> 0.88758126 | CC9: =_Engine_R50!I110/12 -> 0.87564156 | CD9: =_Engine_R50!I111/12 -> 0.86386248 | CE9: =_Engine_R50!I112/12 -> 0.85224184 | CF9: =_Engine_R50!I113/12 -> 0.84077753 | CG9: =_Engine_R50!I114/12 -> 0.82946744 | CH9: =_Engine_R50!I115/12 -> 0.81830949 | CI9: =_Engine_R50!I116/12 -> 0.80730163 | CJ9: =_Engine_R50!I117/12 -> 0.79644185 | CK9: =_Engine_R50!I118/12 -> 0.78572816 | CL9: =_Engine_R50!I119/12 -> 0.77515858 | CM9: =_Engine_R50!I120/12 -> 0.76473119 | CN9: =_Engine_R50!I121/12 -> 0.75444407 | CO9: =_Engine_R50!I122/12 -> 0.74429533 | CP9: =_Engine_R50!I123/12 -> 0.73428311 | CQ9: =_Engine_R50!I124/12 -> 0.72440557 | CR9: =_Engine_R50!I125/12 -> 0.7146609 | CS9: =_Engine_R50!I126/12 -> 0.70504732 | CT9: =_Engine_R50!I127/12 -> 0.69556306 | CU9: =_Engine_R50!I128/12 -> 0.68620639 | CV9: =_Engine_R50!I129/12 -> 0.67697557 | CW9: =_Engine_R50!I130/12 -> 0.66786893 | CX9: =_Engine_R50!I131/12 -> 0.6588848 | CY9: =_Engine_R50!I132/12 -> 0.65002151 | CZ9: =_Engine_R50!I133/12 -> 0.64127746 | DA9: =_Engine_R50!I134/12 -> 0.63265103 | DB9: =_Engine_R50!I135/12 -> 0.62414064 | DC9: =_Engine_R50!I136/12 -> 0.61574473 | DD9: =_Engine_R50!I137/12 -> 0.60746177 | DE9: =_Engine_R50!I138/12 -> 0.59929022 | DF9: =_Engine_R50!I139/12 -> 0.5912286 | DG9: =_Engine_R50!I140/12 -> 0.58327543 | DH9: =_Engine_R50!I141/12 -> 0.57542924 | DI9: =_Engine_R50!I142/12 -> 0.56768859 | DJ9: =_Engine_R50!I143/12 -> 0.56005208 | DK9: =_Engine_R50!I144/12 -> 0.55251829 | DL9: =_Engine_R50!I145/12 -> 0.54508584 | DM9: =_Engine_R50!I146/12 -> 0.53775337 | DN9: =_Engine_R50!I147/12 -> 0.53051954 | DO9: =_Engine_R50!I148/12 -> 0.52338302 | DP9: =_Engine_R50!I149/12 -> 0.5163425 | DQ9: =_Engine_R50!I150/12 -> 0.50939669 | DR9: =_Engine_R50!I151/12 -> 0.50254431 | DS9: =_Engine_R50!I152/12 -> 0.49578411 | DT9: =_Engine_R50!I153/12 -> 0.48911485 | DU9: =_Engine_R50!I154/12 -> 0.4825353 | DV9: =_Engine_R50!I155/12 -> 0.47604427 | DW9: =_Engine_R50!I156/12 -> 0.46964054 | DX9: =_Engine_R50!I157/12 -> 0.46332296 | DY9: =_Engine_R50!I158/12 -> 0.45709037 | DZ9: =_Engine_R50!I159/12 -> 0.45094161 | EA9: =_Engine_R50!I160/12 -> 0.44487557 | EB9: =_Engine_R50!I161/12 -> 0.43889113 | EC9: =_Engine_R50!I162/12 -> 0.43298719 | ED9: =_Engine_R50!I163/12 -> 0.42716267 | EE9: =_Engine_R50!I164/12 -> 0.4214165 | EF9: =_Engine_R50!I165/12 -> 0.41574762 | EG9: =_Engine_R50!I166/12 -> 0.41015501 | EH9: =_Engine_R50!I167/12 -> 0.40463763 | EI9: =_Engine_R50!I168/12 -> 0.39919446 | EJ9: =_Engine_R50!I169/12 -> 0.39382452 | EK9: =_Engine_R50!I170/12 -> 0.38852681 | EL9: =_Engine_R50!I171/12 -> 0.38330037 | EM9: =_Engine_R50!I172/12 -> 0.37814423 | EN9: =_Engine_R50!I173/12 -> 0.37305746 | EO9: =_Engine_R50!I174/12 -> 0.36803911 | EP9: =_Engine_R50!I175/12 -> 0.36308827 | EQ9: =_Engine_R50!I176/12 -> 0.35820402 | ER9: =_Engine_R50!I177/12 -> 0.35338548 | ES9: =_Engine_R50!I178/12 -> 0.34863176 | ET9: =_Engine_R50!I179/12 -> 0.34394198 | EU9: =_Engine_R50!I180/12 -> 0.33931529 | EV9: =_Engine_R50!I181/12 -> 0.33475084 | EW9: =_Engine_R50!I182/12 -> 0.33024779 | EX9: =_Engine_R50!I183/12 -> 0.32580531 | EY9: =_Engine_R50!I184/12 -> 0.3214226 | EZ9: =_Engine_R50!I185/12 -> 0.31709884 | FA9: =_Engine_R50!I186/12 -> 0.31283324 | FB9: =_Engine_R50!I187/12 -> 0.30862503 | FC9: =_Engine_R50!I188/12 -> 0.30447342 | FD9: =_Engine_R50!I189/12 -> 0.30037766 | FE9: =_Engine_R50!I190/12 -> 0.29633699 | FF9: =_Engine_R50!I191/12 -> 0.29235068 | FG9: =_Engine_R50!I192/12 -> 0.288418 | FH9: =_Engine_R50!I193/12 -> 0.28453821 | FI9: =_Engine_R50!I194/12 -> 0.28071062 | FJ9: =_Engine_R50!I195/12 -> 0.27693452 | FK9: =_Engine_R50!I196/12 -> 0.27320921 | FL9: =_Engine_R50!I197/12 -> 0.26953401 | FM9: =_Engine_R50!I198/12 -> 0.26590826 | FN9: =_Engine_R50!I199/12 -> 0.26233127 | FO9: =_Engine_R50!I200/12 -> 0.25880241 | FP9: =_Engine_R50!I201/12 -> 0.25532101 | FQ9: =_Engine_R50!I202/12 -> 0.25188644 | FR9: =_Engine_R50!I203/12 -> 0.24849808 | FS9: =_Engine_R50!I204/12 -> 0.2451553 | FT9: =_Engine_R50!I205/12 -> 0.24185748 | FU9: =_Engine_R50!I206/12 -> 0.23860403 | FV9: =_Engine_R50!I207/12 -> 0.23539434 | FW9: =_Engine_R50!I208/12 -> 0.23222783 | FX9: =_Engine_R50!I209/12 -> 0.22910391 | FY9: =_Engine_R50!I210/12 -> 0.22602202
A10: Deal #5 | B10: =_Engine_R50!J31/12 -> 0 | C10: =_Engine_R50!J32/12 -> 0 | D10: =_Engine_R50!J33/12 -> 0 | E10: =_Engine_R50!J34/12 -> 0 | F10: =_Engine_R50!J35/12 -> 0 | G10: =_Engine_R50!J36/12 -> 0 | H10: =_Engine_R50!J37/12 -> 0 | I10: =_Engine_R50!J38/12 -> 0 | J10: =_Engine_R50!J39/12 -> 0 | K10: =_Engine_R50!J40/12 -> 0 | L10: =_Engine_R50!J41/12 -> 0 | M10: =_Engine_R50!J42/12 -> 0 | N10: =_Engine_R50!J43/12 -> 0 | O10: =_Engine_R50!J44/12 -> 0 | P10: =_Engine_R50!J45/12 -> 0 | Q10: =_Engine_R50!J46/12 -> 0 | R10: =_Engine_R50!J47/12 -> 0 | S10: =_Engine_R50!J48/12 -> 0 | T10: =_Engine_R50!J49/12 -> 0 | U10: =_Engine_R50!J50/12 -> 0 | V10: =_Engine_R50!J51/12 -> 0 | W10: =_Engine_R50!J52/12 -> 0 | X10: =_Engine_R50!J53/12 -> 0 | Y10: =_Engine_R50!J54/12 -> 0 | Z10: =_Engine_R50!J55/12 -> 0 | AA10: =_Engine_R50!J56/12 -> 0 | AB10: =_Engine_R50!J57/12 -> 0 | AC10: =_Engine_R50!J58/12 -> 0 | AD10: =_Engine_R50!J59/12 -> 0 | AE10: =_Engine_R50!J60/12 -> 0 | AF10: =_Engine_R50!J61/12 -> 0 | AG10: =_Engine_R50!J62/12 -> 1.5 | AH10: =_Engine_R50!J63/12 -> 1.493602 | AI10: =_Engine_R50!J64/12 -> 1.4872313 | AJ10: =_Engine_R50!J65/12 -> 1.4808878 | AK10: =_Engine_R50!J66/12 -> 1.4745714 | AL10: =_Engine_R50!J67/12 -> 1.4682818 | AM10: =_Engine_R50!J68/12 -> 1.4620192 | AN10: =_Engine_R50!J69/12 -> 1.4557832 | AO10: =_Engine_R50!J70/12 -> 1.4495738 | AP10: =_Engine_R50!J71/12 -> 1.4433909 | AQ10: =_Engine_R50!J72/12 -> 1.4372344 | AR10: =_Engine_R50!J73/12 -> 1.4311041 | AS10: =_Engine_R50!J74/12 -> 1.425 | AT10: =_Engine_R50!J75/12 -> 1.4189219 | AU10: =_Engine_R50!J76/12 -> 1.4128698 | AV10: =_Engine_R50!J77/12 -> 1.4068434 | AW10: =_Engine_R50!J78/12 -> 1.4008428 | AX10: =_Engine_R50!J79/12 -> 1.3948677 | AY10: =_Engine_R50!J80/12 -> 1.3889182 | AZ10: =_Engine_R50!J81/12 -> 1.382994 | BA10: =_Engine_R50!J82/12 -> 1.3770951 | BB10: =_Engine_R50!J83/12 -> 1.3712214 | BC10: =_Engine_R50!J84/12 -> 1.3653727 | BD10: =_Engine_R50!J85/12 -> 1.3595489 | BE10: =_Engine_R50!J86/12 -> 1.35375 | BF10: =_Engine_R50!J87/12 -> 1.3479758 | BG10: =_Engine_R50!J88/12 -> 1.3422263 | BH10: =_Engine_R50!J89/12 -> 1.3365013 | BI10: =_Engine_R50!J90/12 -> 1.3308007 | BJ10: =_Engine_R50!J91/12 -> 1.3251244 | BK10: =_Engine_R50!J92/12 -> 1.3194723 | BL10: =_Engine_R50!J93/12 -> 1.3138443 | BM10: =_Engine_R50!J94/12 -> 1.3082403 | BN10: =_Engine_R50!J95/12 -> 1.3026603 | BO10: =_Engine_R50!J96/12 -> 1.297104 | BP10: =_Engine_R50!J97/12 -> 1.2915715 | BQ10: =_Engine_R50!J98/12 -> 1.2860625 | BR10: =_Engine_R50!J99/12 -> 1.280577 | BS10: =_Engine_R50!J100/12 -> 1.275115 | BT10: =_Engine_R50!J101/12 -> 1.2696762 | BU10: =_Engine_R50!J102/12 -> 1.2642606 | BV10: =_Engine_R50!J103/12 -> 1.2588681 | BW10: =_Engine_R50!J104/12 -> 1.2534987 | BX10: =_Engine_R50!J105/12 -> 1.2481521 | BY10: =_Engine_R50!J106/12 -> 1.2428283 | BZ10: =_Engine_R50!J107/12 -> 1.2375273 | CA10: =_Engine_R50!J108/12 -> 1.2322488 | CB10: =_Engine_R50!J109/12 -> 1.2269929 | CC10: =_Engine_R50!J110/12 -> 1.2217594 | CD10: =_Engine_R50!J111/12 -> 1.2165482 | CE10: =_Engine_R50!J112/12 -> 1.2113592 | CF10: =_Engine_R50!J113/12 -> 1.2061924 | CG10: =_Engine_R50!J114/12 -> 1.2010476 | CH10: =_Engine_R50!J115/12 -> 1.1959247 | CI10: =_Engine_R50!J116/12 -> 1.1908237 | CJ10: =_Engine_R50!J117/12 -> 1.1857445 | CK10: =_Engine_R50!J118/12 -> 1.1806869 | CL10: =_Engine_R50!J119/12 -> 1.1756509 | CM10: =_Engine_R50!J120/12 -> 1.1706364 | CN10: =_Engine_R50!J121/12 -> 1.1656432 | CO10: =_Engine_R50!J122/12 -> 1.1606714 | CP10: =_Engine_R50!J123/12 -> 1.1557208 | CQ10: =_Engine_R50!J124/12 -> 1.1507913 | CR10: =_Engine_R50!J125/12 -> 1.1458828 | CS10: =_Engine_R50!J126/12 -> 1.1409952 | CT10: =_Engine_R50!J127/12 -> 1.1361285 | CU10: =_Engine_R50!J128/12 -> 1.1312825 | CV10: =_Engine_R50!J129/12 -> 1.1264573 | CW10: =_Engine_R50!J130/12 -> 1.1216526 | CX10: =_Engine_R50!J131/12 -> 1.1168684 | CY10: =_Engine_R50!J132/12 -> 1.1121046 | CZ10: =_Engine_R50!J133/12 -> 1.1073611 | DA10: =_Engine_R50!J134/12 -> 1.1026378 | DB10: =_Engine_R50!J135/12 -> 1.0979347 | DC10: =_Engine_R50!J136/12 -> 1.0932517 | DD10: =_Engine_R50!J137/12 -> 1.0885886 | DE10: =_Engine_R50!J138/12 -> 1.0839454 | DF10: =_Engine_R50!J139/12 -> 1.0793221 | DG10: =_Engine_R50!J140/12 -> 1.0747184 | DH10: =_Engine_R50!J141/12 -> 1.0701344 | DI10: =_Engine_R50!J142/12 -> 1.0655699 | DJ10: =_Engine_R50!J143/12 -> 1.0610249 | DK10: =_Engine_R50!J144/12 -> 1.0564993 | DL10: =_Engine_R50!J145/12 -> 1.051993 | DM10: =_Engine_R50!J146/12 -> 1.0475059 | DN10: =_Engine_R50!J147/12 -> 1.043038 | DO10: =_Engine_R50!J148/12 -> 1.0385891 | DP10: =_Engine_R50!J149/12 -> 1.0341592 | DQ10: =_Engine_R50!J150/12 -> 1.0297482 | DR10: =_Engine_R50!J151/12 -> 1.025356 | DS10: =_Engine_R50!J152/12 -> 1.0209825 | DT10: =_Engine_R50!J153/12 -> 1.0166277 | DU10: =_Engine_R50!J154/12 -> 1.0122914 | DV10: =_Engine_R50!J155/12 -> 1.0079737 | DW10: =_Engine_R50!J156/12 -> 1.0036744 | DX10: =_Engine_R50!J157/12 -> 0.99939338 | DY10: =_Engine_R50!J158/12 -> 0.99513065 | DZ10: =_Engine_R50!J159/12 -> 0.9908861 | EA10: =_Engine_R50!J160/12 -> 0.98665965 | EB10: =_Engine_R50!J161/12 -> 0.98245123 | EC10: =_Engine_R50!J162/12 -> 0.97826077 | ED10: =_Engine_R50!J163/12 -> 0.97408817 | EE10: =_Engine_R50!J164/12 -> 0.96993338 | EF10: =_Engine_R50!J165/12 -> 0.9657963 | EG10: =_Engine_R50!J166/12 -> 0.96167687 | EH10: =_Engine_R50!J167/12 -> 0.95757501 | EI10: =_Engine_R50!J168/12 -> 0.95349065 | EJ10: =_Engine_R50!J169/12 -> 0.94942371 | EK10: =_Engine_R50!J170/12 -> 0.94537411 | EL10: =_Engine_R50!J171/12 -> 0.94134179 | EM10: =_Engine_R50!J172/12 -> 0.93732667 | EN10: =_Engine_R50!J173/12 -> 0.93332867 | EO10: =_Engine_R50!J174/12 -> 0.92934773 | EP10: =_Engine_R50!J175/12 -> 0.92538376 | EQ10: =_Engine_R50!J176/12 -> 0.92143671 | ER10: =_Engine_R50!J177/12 -> 0.91750649 | ES10: =_Engine_R50!J178/12 -> 0.91359303 | ET10: =_Engine_R50!J179/12 -> 0.90969626 | EU10: =_Engine_R50!J180/12 -> 0.90581612 | EV10: =_Engine_R50!J181/12 -> 0.90195252 | EW10: =_Engine_R50!J182/12 -> 0.89810541 | EX10: =_Engine_R50!J183/12 -> 0.8942747 | EY10: =_Engine_R50!J184/12 -> 0.89046034 | EZ10: =_Engine_R50!J185/12 -> 0.88666224 | FA10: =_Engine_R50!J186/12 -> 0.88288034 | FB10: =_Engine_R50!J187/12 -> 0.87911458 | FC10: =_Engine_R50!J188/12 -> 0.87536487 | FD10: =_Engine_R50!J189/12 -> 0.87163116 | FE10: =_Engine_R50!J190/12 -> 0.86791338 | FF10: =_Engine_R50!J191/12 -> 0.86421145 | FG10: =_Engine_R50!J192/12 -> 0.86052531 | FH10: =_Engine_R50!J193/12 -> 0.8568549 | FI10: =_Engine_R50!J194/12 -> 0.85320014 | FJ10: =_Engine_R50!J195/12 -> 0.84956097 | FK10: =_Engine_R50!J196/12 -> 0.84593732 | FL10: =_Engine_R50!J197/12 -> 0.84232913 | FM10: =_Engine_R50!J198/12 -> 0.83873632 | FN10: =_Engine_R50!J199/12 -> 0.83515885 | FO10: =_Engine_R50!J200/12 -> 0.83159663 | FP10: =_Engine_R50!J201/12 -> 0.8280496 | FQ10: =_Engine_R50!J202/12 -> 0.82451771 | FR10: =_Engine_R50!J203/12 -> 0.82100088 | FS10: =_Engine_R50!J204/12 -> 0.81749905 | FT10: =_Engine_R50!J205/12 -> 0.81401215 | FU10: =_Engine_R50!J206/12 -> 0.81054013 | FV10: =_Engine_R50!J207/12 -> 0.80708292 | FW10: =_Engine_R50!J208/12 -> 0.80364045 | FX10: =_Engine_R50!J209/12 -> 0.80021267 | FY10: =_Engine_R50!J210/12 -> 0.79679951
