Workbook

Sheet 1. Press Assumptions
A1: PRESS CAPITAL -- Fund I ASSUMPTIONS
A2: All blue cells are adjustable inputs. Black cells on gray are calculated. | D2: UNDERWRITING SCENARIO set in B136 below (Bear 80% / Base 85% / Bull 90%).
D3: ACTIVE: $150M, 50% RECYCLE. NDR 80/90/100 (Yr1-6) -> 85% decay (Yr7+). 5 base + 3 recycled (M24/32/40).
A4: FUND PARAMETERS
A5: Fund Size ($) | B5: 150000000 | C5: Raised from $150M to fix -$0.4M cushion (LPs slightly increased).
A6: Number of Deals | B6: 5
A7: ARR per Deal ($) | B7: 24000000
A8: Entry Multiple (x ARR) | B8: 1.25
A9: Capital per Deal ($) | B9: 30000000 | E9: ARR x Entry Multiple (auto)
A10: Total Capital Deployed ($) | B10: 150000000 | E10: Deals x Capital per Deal (auto)
A11: Asset Deal % (50% rev haircut Y1) | B11: 0.25
A12: Share Deal % | B12: 0.75 | E12: 1 - Asset Deal %
A13: Leverage / Debt | B13: Zero | E13: No debt at fund or portfolio company level. All cash acquisitions.
A15: RETENTION & GROWTH
A16: Net Dollar Retention -- Base Case | B16: 0.85
A17: Net Dollar Retention -- Homerun | B17: 0.95
A18: Net Dollar Retention -- Looser | B18: 0.8 | E18: Conservative / stress test scenario
A19: NCA % -- Base Case | B19: 0
A20: NCA % -- Homerun | B20: 0.05
A21: Scenario Toggle (1=Base, 2=Homerun) | B21: 1 | E21: 1=Base, 2=Homerun, 3=Looser
A22: Active Retention Rate | B22: 0.85 | E22: Auto from toggle
A23: Active NCA Rate | B23: 0 | E23: Auto from toggle
A25: MARGIN MODEL
A26: Net Margin (flat, all years) | B26: 0.625 | E26: Used in flat-margin tabs (3a-3d). Set to 0 to use component costs.
A28: COST STRUCTURE
A29: All companies assumed breakeven at entry. Adjust per-deal entry margin on Tab 2.
A30: COGS | B30: 0.1 | E30: Ramps from 25% at close to 10% over 6 months
A31: Vendor Costs | B31: 0.05 | E31: Ramps from 10% at close to 5% over 6 months
A32: Corporate Allocation | B32: 0.06 | E32: Flat
A33: Legacy Headcount Expenses | B33: 0 | E33: Acquired company staff. 50% cut day 1, 90% by M6, 100% by M24. Rate derived from entry profit per deal.
A34: Salary Overhead Loading | B34: 0.3 | E34: On top of base salaries
A35: Bonus Pool Threshold | B35: 1 | C35: Set to 100% per GP -- no bonus pool. All margin upside flows to investors. | E35: Included in OpEx. Everything above 62.5% EBITDA margin goes to team.
A37: WATERFALL & DISTRIBUTION
A38: Phase 1: Return of Capital (x) | B38: 1 | E38: 100% to LPs until 1x returned
A39: Preferred Return (Annual) | B39: 0.1 | E39: 10% pref on unreturned capital
A40: Tier 2: LP Split % (1x-2x) | B40: 0.8 | E40: HoldCo gets 20%
A41: Tier 3: LP Split % (2x-3x) | B41: 0.75 | E41: HoldCo gets 25%
A42: Tier 4: LP Split % (above 3x) | B42: 0.7 | E42: HoldCo gets 30% -- perpetual
A43: Mgmt Fee Schedule | B43: 2% Y1 only | E43: 0% after Y1 once 3 deals deployed
A45: TIERED WATERFALL THRESHOLDS
...

Sheet 2. LP Economics
A1: LP ECONOMICS BY COMMITMENT SIZE
A2: Live from engines. Returns are SIZE-INVARIANT (DPI/IRR same across commit sizes). Cash scales linearly.
A3: =" Active scenario (Tab 1 B136): " & '1. Press Assumptions'!$B$136 & " | Toggle Bull / Base / Bear on Tab 1 to recalc this tab."
B4: $5M | E4: $10M | H4: $25M
B5: No Recycle | C5: 50% Recycle | D5: 100% Recycle | E5: No Recycle | F5: 50% Recycle | G5: 100% Recycle | H5: No Recycle | I5: 50% Recycle | J5: 100% Recycle
A7: FUND PARTICIPATION
A8: Commitment | B8: 5 | C8: 5 | D8: 5 | E8: 10 | F8: 10 | G8: 10 | H8: 25 | I8: 25 | J8: 25
A9: Payback (months) | B9: TBD | C9: TBD | D9: TBD | E9: TBD | F9: TBD | G9: TBD | H9: TBD | I9: TBD | J9: TBD
A11: 10-YEAR RETURNS
A12: LP Net IRR (Staged) | B12: ='_Engine_NR'!$B$277 | C12: ='_Engine_R50'!$B$277 | D12: ='_Engine_R100'!$B$277 | E12: ='_Engine_NR'!$B$277 | F12: ='_Engine_R50'!$B$277 | G12: ='_Engine_R100'!$B$277 | H12: ='_Engine_NR'!$B$277 | I12: ='_Engine_R50'!$B$277 | J12: ='_Engine_R100'!$B$277
A13: LP MOIC / DPI | B13: ='_Engine_NR'!$B$254 | C13: ='_Engine_R50'!$B$254 | D13: ='_Engine_R100'!$B$254 | E13: ='_Engine_NR'!$B$254 | F13: ='_Engine_R50'!$B$254 | G13: ='_Engine_R100'!$B$254 | H13: ='_Engine_NR'!$B$254 | I13: ='_Engine_R50'!$B$254 | J13: ='_Engine_R100'!$B$254
A14: Cash Distributed | B14: =B13*B8 | C14: =C13*C8 | D14: =D13*D8 | E14: =E13*E8 | F14: =F13*F8 | G14: =G13*G8 | H14: =H13*H8 | I14: =I13*I8 | J14: =J13*J8
A16: 15-YEAR RETURNS
A17: LP Net IRR (Staged) | B17: ='_Engine_NR'!$B$276 | C17: ='_Engine_R50'!$B$276 | D17: ='_Engine_R100'!$B$276 | E17: ='_Engine_NR'!$B$276 | F17: ='_Engine_R50'!$B$276 | G17: ='_Engine_R100'!$B$276 | H17: ='_Engine_NR'!$B$276 | I17: ='_Engine_R50'!$B$276 | J17: ='_Engine_R100'!$B$276
A18: LP MOIC / DPI | B18: ='_Engine_NR'!$B$252 | C18: ='_Engine_R50'!$B$252 | D18: ='_Engine_R100'!$B$252 | E18: ='_Engine_NR'!$B$252 | F18: ='_Engine_R50'!$B$252 | G18: ='_Engine_R100'!$B$252 | H18: ='_Engine_NR'!$B$252 | I18: ='_Engine_R50'!$B$252 | J18: ='_Engine_R100'!$B$252
A19: Total Cash | B19: =B18*B8 | C19: =C18*C8 | D19: =D18*D8 | E19: =E18*E8 | F19: =F18*F8 | G19: =G18*G8 | H19: =H18*H8 | I19: =I18*I8 | J19: =J18*J8
A21: NOTE: returns above are identical across commitment sizes (the model has no LP class differentiation).
A22: See Tab 11 for NDR x Margin joint sensitivity. See Tab 20 for quarterly cash schedule.
B31: 0 | C31: 0 | D31: 0 | E31: 0 | F31: 0 | G31: 0 | H31: 0 | I31: 0 | J31: 0
D32: 0 | G32: 0 | J32: 0
D33: 0 | G33: 0 | J33: 0
B45: 0 | E45: 0 | H45: 0
A50: POTENTIAL LP CLASS STRUCTURE (placeholder -- not in deck)
A51: Class | B51: Min commit | C51: Mgmt fee discount | D51: Co-invest pro-rata | E51: LPAC seat | F51: Notes
A52: Standard | B52: $1M | C52: None | D52: None | E52: No | F52: Default class. No structural differentiation in deck.
A53: Co-invest eligible | B53: $10M | C53: None | D53: Yes (placeholder) | E53: No | F53: Not actually offered.
A54: LPAC | B54: $25M | C54: None | D54: Yes (placeholder) | E54: Yes (placeholder) | F54: Standard market term.
A55: Anchor | B55: $50M+ | C55: 25-50% (placeholder) | D55: Yes (placeholder) | E55: Yes (placeholder) | F55: Anchor LPs typically negotiate fee discount.
A56: LP should ask: are any of the above terms negotiable? Side-letter MFN clause? Anchor commitments?

Sheet 3. Deal Allocation
A1: PRESS CAPITAL -- DEAL ALLOCATION
A2: =" Scenario-driven. NDR = "&TEXT(IF('1. Press Assumptions'!$B$136="Bear",0.8,IF('1. Press Assumptions'!$B$136="Bull",0.9,0.85)),"0%")&" (Tab 1 B136). 1.24x entry. 50/50 sev split."
A4: Deal | B4: ARR ($mm) | C4: Entry Mult | D4: Gross Price | E4: Sev Disc | F4: Net Price | G4: NDR | H4: Entry Profit | I4: Close Mo
A5: #1 | B5: ='1. Press Assumptions'!$D$89 | C5: ='1. Press Assumptions'!$E$89 | D5: =B5*C5 | E5: =B5*0.1154*0.5 | F5: =D5-E5 | G5: =IF('1. Press Assumptions'!$B$136="Bear",0.8,IF('1. Press Assumptions'!$B$136="Bull",0.9,0.85)) | H5: 0 | I5: ="M"&'1. Press Assumptions'!$K$89
A6: #2 | B6: ='1. Press Assumptions'!$D$90 | C6: ='1. Press Assumptions'!$E$90 | D6: =B6*C6 | E6: =B6*0.1154*0.5 | F6: =D6-E6 | G6: =IF('1. Press Assumptions'!$B$136="Bear",0.8,IF('1. Press Assumptions'!$B$136="Bull",0.9,0.85)) | H6: 0 | I6: ="M"&'1. Press Assumptions'!$K$90
A7: #3 | B7: ='1. Press Assumptions'!$D$91 | C7: ='1. Press Assumptions'!$E$91 | D7: =B7*C7 | E7: =B7*0.1154*0.5 | F7: =D7-E7 | G7: =IF('1. Press Assumptions'!$B$136="Bear",0.8,IF('1. Press Assumptions'!$B$136="Bull",0.9,0.85)) | H7: 0 | I7: ="M"&'1. Press Assumptions'!$K$91
A8: #4 | B8: ='1. Press Assumptions'!$D$92 | C8: ='1. Press Assumptions'!$E$92 | D8: =B8*C8 | E8: =B8*0.1154*0.5 | F8: =D8-E8 | G8: =IF('1. Press Assumptions'!$B$136="Bear",0.8,IF('1. Press Assumptions'!$B$136="Bull",0.9,0.85)) | H8: 0 | I8: ="M"&'1. Press Assumptions'!$K$92
A9: #5 | B9: ='1. Press Assumptions'!$D$93 | C9: ='1. Press Assumptions'!$E$93 | D9: =B9*C9 | E9: =B9*0.1154*0.5 | F9: =D9-E9 | G9: =IF('1. Press Assumptions'!$B$136="Bear",0.8,IF('1. Press Assumptions'!$B$136="Bull",0.9,0.85)) | H9: 0 | I9: ="M"&'1. Press Assumptions'!$K$93
A11: TOTAL | B11: =SUM(B5:B9) | D11: =SUM(D5:D9) | E11: =SUM(E5:E9) | F11: =SUM(F5:F9)
A13: RECYCLED DEALS (50% retention, M1-36)
A14: Deal | B14: ARR ($mm) | C14: Entry Mult | D14: Gross Price | E14: Sev Disc | F14: Net Price | G14: NDR | H14: Entry Profit | I14: Close Mo
A15: #6 | B15: ='1. Press Assumptions'!$D$96 | C15: ='1. Press Assumptions'!$E$96 | D15: =B15*C15 | E15: =B15*0.1154*0.5 | F15: =D15-E15 | G15: =IF('1. Press Assumptions'!$B$136="Bear",0.8,IF('1. Press Assumptions'!$B$136="Bull",0.9,0.85)) | H15: 0 | I15: ="M"&'1. Press Assumptions'!$K$96
A16: #7 | B16: ='1. Press Assumptions'!$D$97 | C16: ='1. Press Assumptions'!$E$97 | D16: =B16*C16 | E16: =B16*0.1154*0.5 | F16: =D16-E16 | G16: =IF('1. Press Assumptions'!$B$136="Bear",0.8,IF('1. Press Assumptions'!$B$136="Bull",0.9,0.85)) | H16: 0 | I16: ="M"&'1. Press Assumptions'!$K$97
A17: #8 | B17: ='1. Press Assumptions'!$D$98 | C17: ='1. Press Assumptions'!$E$98 | D17: =B17*C17 | E17: =B17*0.1154*0.5 | F17: =D17-E17 | G17: =IF('1. Press Assumptions'!$B$136="Bear",0.8,IF('1. Press Assumptions'!$B$136="Bull",0.9,0.85)) | H17: 0 | I17: ="M"&'1. Press Assumptions'!$K$98
A18: #9 | B18: ='1. Press Assumptions'!$D$99 | C18: ='1. Press Assumptions'!$E$99 | D18: =B18*C18 | E18: =B18*0.1154*0.5 | F18: =D18-E18 | G18: =IF('1. Press Assumptions'!$B$136="Bear",0.8,IF('1. Press Assumptions'!$B$136="Bull",0.9,0.85)) | H18: 0 | I18: ="M"&'1. Press Assumptions'!$K$99
A42: Green = premium (profitable + growing). Gold = par. Red = distress discount.

Sheet 4a. Annual P&L (No Recycle)
A1: PRESS CAPITAL -- FUND I P&L | NO RECYCLING | I1: ="Active scenario: " & '1. Press Assumptions'!$B$136 & " (toggle on Tab 1 B136)"
A2: 5 deals @ $24M ARR. Per-deal NDR mix.. LIVE from _Engine_NR -- Tab 1 inputs flow through.
A3: ($mm) | B3: Total | C3: Year 1 | D3: Year 2 | E3: Year 3 | F3: Year 4 | G3: Year 5 | H3: Year 6 | I3: Year 7 | J3: Year 8 | K3: Year 9 | L3: Year 10 | M3: Year 11 | N3: Year 12 | O3: Year 13 | P3: Year 14 | Q3: Year 15
A5: Revenue | B5: =SUM(C5:Q5) | C5: ='_Engine_NR'!B215 | D5: ='_Engine_NR'!B216 | E5: ='_Engine_NR'!B217 | F5: ='_Engine_NR'!B218 | G5: ='_Engine_NR'!B219 | H5: ='_Engine_NR'!B220 | I5: ='_Engine_NR'!B221 | J5: ='_Engine_NR'!B222 | K5: ='_Engine_NR'!B223 | L5: ='_Engine_NR'!B224 | M5: ='_Engine_NR'!B225 | N5: ='_Engine_NR'!B226 | O5: ='_Engine_NR'!B227 | P5: ='_Engine_NR'!B228 | Q5: ='_Engine_NR'!B229
A6: Cost of Goods Sold | B6: =SUM(C6:Q6) | C6: ='_Engine_NR'!C215 | D6: ='_Engine_NR'!C216 | E6: ='_Engine_NR'!C217 | F6: ='_Engine_NR'!C218 | G6: ='_Engine_NR'!C219 | H6: ='_Engine_NR'!C220 | I6: ='_Engine_NR'!C221 | J6: ='_Engine_NR'!C222 | K6: ='_Engine_NR'!C223 | L6: ='_Engine_NR'!C224 | M6: ='_Engine_NR'!C225 | N6: ='_Engine_NR'!C226 | O6: ='_Engine_NR'!C227 | P6: ='_Engine_NR'!C228 | Q6: ='_Engine_NR'!C229
A7: Gross Profit | B7: =SUM(C7:Q7) | C7: =C5-C6 | D7: =D5-D6 | E7: =E5-E6 | F7: =F5-F6 | G7: =G5-G6 | H7: =H5-H6 | I7: =I5-I6 | J7: =J5-J6 | ... Q7: =Q5-Q6
A9: Operating Expenses
A10: Vendor Costs | B10: =SUM(C10:Q10) | C10: ='_Engine_NR'!D215 | D10: ='_Engine_NR'!D216 | E10: ='_Engine_NR'!D217 | F10: ='_Engine_NR'!D218 | G10: ='_Engine_NR'!D219 | H10: ='_Engine_NR'!D220 | I10: ='_Engine_NR'!D221 | J10: ='_Engine_NR'!D222 | K10: ='_Engine_NR'!D223 | L10: ='_Engine_NR'!D224 | M10: ='_Engine_NR'!D225 | N10: ='_Engine_NR'!D226 | O10: ='_Engine_NR'!D227 | P10: ='_Engine_NR'!D228 | Q10: ='_Engine_NR'!D229
A11: Corporate Allocation | B11: =SUM(C11:Q11) | C11: ='_Engine_NR'!E215 | D11: ='_Engine_NR'!E216 | E11: ='_Engine_NR'!E217 | F11: ='_Engine_NR'!E218 | G11: ='_Engine_NR'!E219 | H11: ='_Engine_NR'!E220 | I11: ='_Engine_NR'!E221 | J11: ='_Engine_NR'!E222 | K11: ='_Engine_NR'!E223 | L11: ='_Engine_NR'!E224 | M11: ='_Engine_NR'!E225 | N11: ='_Engine_NR'!E226 | O11: ='_Engine_NR'!E227 | P11: ='_Engine_NR'!E228 | Q11: ='_Engine_NR'!E229
A12: Team Compensation | B12: =SUM(C12:Q12) | C12: ='_Engine_NR'!F215 | D12: ='_Engine_NR'!F216 | E12: ='_Engine_NR'!F217 | F12: ='_Engine_NR'!F218 | G12: ='_Engine_NR'!F219 | H12: ='_Engine_NR'!F220 | I12: ='_Engine_NR'!F221 | J12: ='_Engine_NR'!F222 | K12: ='_Engine_NR'!F223 | L12: ='_Engine_NR'!F224 | M12: ='_Engine_NR'!F225 | N12: ='_Engine_NR'!F226 | O12: ='_Engine_NR'!F227 | P12: ='_Engine_NR'!F228 | Q12: ='_Engine_NR'!F229
A13: Legacy Headcount Expenses | B13: =SUM(C13:Q13) | C13: ='_Engine_NR'!G215 | D13: ='_Engine_NR'!G216 | E13: ='_Engine_NR'!G217 | F13: ='_Engine_NR'!G218 | G13: ='_Engine_NR'!G219 | H13: ='_Engine_NR'!G220 | I13: ='_Engine_NR'!G221 | J13: ='_Engine_NR'!G222 | K13: ='_Engine_NR'!G223 | L13: ='_Engine_NR'!G224 | M13: ='_Engine_NR'!G225 | N13: ='_Engine_NR'!G226 | O13: ='_Engine_NR'!G227 | P13: ='_Engine_NR'!G228 | Q13: ='_Engine_NR'!G229
A14: Bonus Pool | B14: =SUM(C14:Q14) | C14: ='_Engine_NR'!H215 | D14: ='_Engine_NR'!H216 | E14: ='_Engine_NR'!H217 | F14: ='_Engine_NR'!H218 | G14: ='_Engine_NR'!H219 | H14: ='_Engine_NR'!H220 | I14: ='_Engine_NR'!H221 | J14: ='_Engine_NR'!H222 | K14: ='_Engine_NR'!H223 | L14: ='_Engine_NR'!H224 | M14: ='_Engine_NR'!H225 | N14: ='_Engine_NR'!H226 | O14: ='_Engine_NR'!H227 | P14: ='_Engine_NR'!H228 | Q14: ='_Engine_NR'!H229
A15: Total Operating Expenses | B15: =SUM(C15:Q15) | C15: =C10+C11+C12+C13+C14 | D15: =D10+D11+D12+D13+D14 | E15: =E10+E11+E12+E13+E14 | F15: =F10+F11+F12+F13+F14 | G15: =G10+G11+G12+G13+G14 | H15: =H10+H11+H12+H13+H14 | I15: =I10+I11+I12+I13+I14 | J15: =J10+J11+J12+J13+J14 | ... Q15: =Q10+Q11+Q12+Q13+Q14
A17: EBITDA | B17: =SUM(C17:Q17) | C17: ='_Engine_NR'!I215 | D17: ='_Engine_NR'!I216 | E17: ='_Engine_NR'!I217 | F17: ='_Engine_NR'!I218 | G17: ='_Engine_NR'!I219 | H17: ='_Engine_NR'!I220 | I17: ='_Engine_NR'!I221 | J17: ='_Engine_NR'!I222 | K17: ='_Engine_NR'!I223 | L17: ='_Engine_NR'!I224 | M17: ='_Engine_NR'!I225 | N17: ='_Engine_NR'!I226 | O17: ='_Engine_NR'!I227 | P17: ='_Engine_NR'!I228 | Q17: ='_Engine_NR'!I229
A18: EBITDA Margin | B18: =B17/B5 | C18: =IF(C5=0,0,C17/C5) | D18: =IF(D5=0,0,D17/D5) | E18: =IF(E5=0,0,E17/E5) | F18: =IF(F5=0,0,F17/F5) | G18: =IF(G5=0,0,G17/G5) | H18: =IF(H5=0,0,H17/H5) | I18: =IF(I5=0,0,I17/I5) | J18: =IF(J5=0,0,J17/J5) | ... Q18: =IF(Q5=0,0,Q17/Q5)
A20: Severance (Press 50%) | B20: =SUM(C20:Q20) | C20: ='_Engine_NR'!J215 | D20: ='_Engine_NR'!J216 | E20: ='_Engine_NR'!J217 | F20: ='_Engine_NR'!J218 | G20: ='_Engine_NR'!J219 | H20: ='_Engine_NR'!J220 | I20: ='_Engine_NR'!J221 | J20: ='_Engine_NR'!J222 | K20: ='_Engine_NR'!J223 | L20: ='_Engine_NR'!J224 | M20: ='_Engine_NR'!J225 | N20: ='_Engine_NR'!J226 | O20: ='_Engine_NR'!J227 | P20: ='_Engine_NR'!J228 | Q20: ='_Engine_NR'!J229
A21: Operating Income | B21: =B17-B20 | C21: =C17-C20 | D21: =D17-D20 | E21: =E17-E20 | F21: =F17-F20 | G21: =G17-G20 | H21: =H17-H20 | I21: =I17-I20 | ... Q21: =Q17-Q20
A23: Management Fee | B23: =SUM(C23:Q23) | C23: ='_Engine_NR'!K215 | D23: ='_Engine_NR'!K216 | E23: ='_Engine_NR'!K217 | F23: ='_Engine_NR'!K218 | G23: ='_Engine_NR'!K219 | H23: ='_Engine_NR'!K220 | I23: ='_Engine_NR'!K221 | J23: ='_Engine_NR'!K222 | K23: ='_Engine_NR'!K223 | L23: ='_Engine_NR'!K224 | M23: ='_Engine_NR'!K225 | N23: ='_Engine_NR'!K226 | O23: ='_Engine_NR'!K227 | P23: ='_Engine_NR'!K228 | Q23: ='_Engine_NR'!K229
A24: Distributable Cash | B24: =SUM(C24:Q24) | C24: =C21-C23 | D24: =D21-D23 | E24: =E21-E23 | F24: =F21-F23 | G24: =G21-G23 | H24: =H21-H23 | I24: =I21-I23 | J24: =J21-J23 | ... Q24: =Q21-Q23
A25: Cumulative Distributable | B25: =Q25 | C25: =C24 | D25: =C25+D24 | E25: =D25+E24 | F25: =E25+F24 | G25: =F25+G24 | H25: =G25+H24 | I25: =H25+I24 | J25: =I25+J24 | K25: =J25+K24 | ... Q25: =P25+Q24

Sheet 4b. Annual P&L (Recycle)
A1: PRESS CAPITAL -- FUND I P&L | 50% RECYCLE x 36mo | I1: ="Active scenario: " & '1. Press Assumptions'!$B$136 & " (toggle on Tab 1 B136)"
A2: 8 deals @ $24M ARR. 50% retained M1-36.. LIVE from _Engine_R50.
A3: ($mm) | B3: Total | C3: Year 1 | D3: Year 2 | E3: Year 3 | F3: Year 4 | G3: Year 5 | H3: Year 6 | I3: Year 7 | J3: Year 8 | K3: Year 9 | L3: Year 10 | M3: Year 11 | N3: Year 12 | O3: Year 13 | P3: Year 14 | Q3: Year 15
A5: Revenue | B5: =SUM(C5:Q5) | C5: ='_Engine_R50'!B215 | D5: ='_Engine_R50'!B216 | E5: ='_Engine_R50'!B217 | F5: ='_Engine_R50'!B218 | G5: ='_Engine_R50'!B219 | H5: ='_Engine_R50'!B220 | I5: ='_Engine_R50'!B221 | J5: ='_Engine_R50'!B222 | K5: ='_Engine_R50'!B223 | L5: ='_Engine_R50'!B224 | M5: ='_Engine_R50'!B225 | N5: ='_Engine_R50'!B226 | O5: ='_Engine_R50'!B227 | P5: ='_Engine_R50'!B228 | Q5: ='_Engine_R50'!B229
A6: Cost of Goods Sold | B6: =SUM(C6:Q6) | C6: ='_Engine_R50'!C215 | D6: ='_Engine_R50'!C216 | E6: ='_Engine_R50'!C217 | F6: ='_Engine_R50'!C218 | G6: ='_Engine_R50'!C219 | H6: ='_Engine_R50'!C220 | I6: ='_Engine_R50'!C221 | J6: ='_Engine_R50'!C222 | K6: ='_Engine_R50'!C223 | L6: ='_Engine_R50'!C224 | M6: ='_Engine_R50'!C225 | N6: ='_Engine_R50'!C226 | O6: ='_Engine_R50'!C227 | P6: ='_Engine_R50'!C228 | Q6: ='_Engine_R50'!C229
A7: Gross Profit | B7: =SUM(C7:Q7) | C7: =C5-C6 | D7: =D5-D6 | E7: =E5-E6 | F7: =F5-F6 | G7: =G5-G6 | H7: =H5-H6 | I7: =I5-I6 | J7: =J5-J6 | ... Q7: =Q5-Q6
A9: Operating Expenses
A10: Vendor Costs | B10: =SUM(C10:Q10) | C10: ='_Engine_R50'!D215 | D10: ='_Engine_R50'!D216 | E10: ='_Engine_R50'!D217 | F10: ='_Engine_R50'!D218 | G10: ='_Engine_R50'!D219 | H10: ='_Engine_R50'!D220 | I10: ='_Engine_R50'!D221 | J10: ='_Engine_R50'!D222 | K10: ='_Engine_R50'!D223 | L10: ='_Engine_R50'!D224 | M10: ='_Engine_R50'!D225 | N10: ='_Engine_R50'!D226 | O10: ='_Engine_R50'!D227 | P10: ='_Engine_R50'!D228 | Q10: ='_Engine_R50'!D229
A11: Corporate Allocation | B11: =SUM(C11:Q11) | C11: ='_Engine_R50'!E215 | D11: ='_Engine_R50'!E216 | E11: ='_Engine_R50'!E217 | F11: ='_Engine_R50'!E218 | G11: ='_Engine_R50'!E219 | H11: ='_Engine_R50'!E220 | I11: ='_Engine_R50'!E221 | J11: ='_Engine_R50'!E222 | K11: ='_Engine_R50'!E223 | L11: ='_Engine_R50'!E224 | M11: ='_Engine_R50'!E225 | N11: ='_Engine_R50'!E226 | O11: ='_Engine_R50'!E227 | P11: ='_Engine_R50'!E228 | Q11: ='_Engine_R50'!E229
A12: Team Compensation | B12: =SUM(C12:Q12) | C12: ='_Engine_R50'!F215 | D12: ='_Engine_R50'!F216 | E12: ='_Engine_R50'!F217 | F12: ='_Engine_R50'!F218 | G12: ='_Engine_R50'!F219 | H12: ='_Engine_R50'!F220 | I12: ='_Engine_R50'!F221 | J12: ='_Engine_R50'!F222 | K12: ='_Engine_R50'!F223 | L12: ='_Engine_R50'!F224 | M12: ='_Engine_R50'!F225 | N12: ='_Engine_R50'!F226 | O12: ='_Engine_R50'!F227 | P12: ='_Engine_R50'!F228 | Q12: ='_Engine_R50'!F229
A13: Legacy Headcount Expenses | B13: =SUM(C13:Q13) | C13: ='_Engine_R50'!G215 | D13: ='_Engine_R50'!G216 | E13: ='_Engine_R50'!G217 | F13: ='_Engine_R50'!G218 | G13: ='_Engine_R50'!G219 | H13: ='_Engine_R50'!G220 | I13: ='_Engine_R50'!G221 | J13: ='_Engine_R50'!G222 | K13: ='_Engine_R50'!G223 | L13: ='_Engine_R50'!G224 | M13: ='_Engine_R50'!G225 | N13: ='_Engine_R50'!G226 | O13: ='_Engine_R50'!G227 | P13: ='_Engine_R50'!G228 | Q13: ='_Engine_R50'!G229
A14: Bonus Pool | B14: =SUM(C14:Q14) | C14: ='_Engine_R50'!H215 | D14: ='_Engine_R50'!H216 | E14: ='_Engine_R50'!H217 | F14: ='_Engine_R50'!H218 | G14: ='_Engine_R50'!H219 | H14: ='_Engine_R50'!H220 | I14: ='_Engine_R50'!H221 | J14: ='_Engine_R50'!H222 | K14: ='_Engine_R50'!H223 | L14: ='_Engine_R50'!H224 | M14: ='_Engine_R50'!H225 | N14: ='_Engine_R50'!H226 | O14: ='_Engine_R50'!H227 | P14: ='_Engine_R50'!H228 | Q14: ='_Engine_R50'!H229
A15: Total Operating Expenses | B15: =SUM(C15:Q15) | C15: =C10+C11+C12+C13+C14 | D15: =D10+D11+D12+D13+D14 | E15: =E10+E11+E12+E13+E14 | F15: =F10+F11+F12+F13+F14 | G15: =G10+G11+G12+G13+G14 | H15: =H10+H11+H12+H13+H14 | I15: =I10+I11+I12+I13+I14 | J15: =J10+J11+J12+J13+J14 | ... Q15: =Q10+Q11+Q12+Q13+Q14
A17: EBITDA | B17: =SUM(C17:Q17) | C17: ='_Engine_R50'!I215 | D17: ='_Engine_R50'!I216 | E17: ='_Engine_R50'!I217 | F17: ='_Engine_R50'!I218 | G17: ='_Engine_R50'!I219 | H17: ='_Engine_R50'!I220 | I17: ='_Engine_R50'!I221 | J17: ='_Engine_R50'!I222 | K17: ='_Engine_R50'!I223 | L17: ='_Engine_R50'!I224 | M17: ='_Engine_R50'!I225 | N17: ='_Engine_R50'!I226 | O17: ='_Engine_R50'!I227 | P17: ='_Engine_R50'!I228 | Q17: ='_Engine_R50'!I229
A18: EBITDA Margin | B18: =B17/B5 | C18: =IF(C5=0,0,C17/C5) | D18: =IF(D5=0,0,D17/D5) | E18: =IF(E5=0,0,E17/E5) | F18: =IF(F5=0,0,F17/F5) | G18: =IF(G5=0,0,G17/G5) | H18: =IF(H5=0,0,H17/H5) | I18: =IF(I5=0,0,I17/I5) | J18: =IF(J5=0,0,J17/J5) | ... Q18: =IF(Q5=0,0,Q17/Q5)
A20: Severance (Press 50%) | B20: =SUM(C20:Q20) | C20: ='_Engine_R50'!J215 | D20: ='_Engine_R50'!J216 | E20: ='_Engine_R50'!J217 | F20: ='_Engine_R50'!J218 | G20: ='_Engine_R50'!J219 | H20: ='_Engine_R50'!J220 | I20: ='_Engine_R50'!J221 | J20: ='_Engine_R50'!J222 | K20: ='_Engine_R50'!J223 | L20: ='_Engine_R50'!J224 | M20: ='_Engine_R50'!J225 | N20: ='_Engine_R50'!J226 | O20: ='_Engine_R50'!J227 | P20: ='_Engine_R50'!J228 | Q20: ='_Engine_R50'!J229
A21: Operating Income | B21: =B17-B20 | C21: =C17-C20 | D21: =D17-D20 | E21: =E17-E20 | F21: =F17-F20 | G21: =G17-G20 | H21: =H17-H20 | I21: =I17-I20 | ... Q21: =Q17-Q20
A23: Management Fee | B23: =SUM(C23:Q23) | C23: ='_Engine_R50'!K215 | D23: ='_Engine_R50'!K216 | E23: ='_Engine_R50'!K217 | F23: ='_Engine_R50'!K218 | G23: ='_Engine_R50'!K219 | H23: ='_Engine_R50'!K220 | I23: ='_Engine_R50'!K221 | J23: ='_Engine_R50'!K222 | K23: ='_Engine_R50'!K223 | L23: ='_Engine_R50'!K224 | M23: ='_Engine_R50'!K225 | N23: ='_Engine_R50'!K226 | O23: ='_Engine_R50'!K227 | P23: ='_Engine_R50'!K228 | Q23: ='_Engine_R50'!K229
A24: Retained for Recycling (50%) | B24: =SUM(C24:Q24) | C24: ='_Engine_R50'!M215 | D24: ='_Engine_R50'!M216 | E24: ='_Engine_R50'!M217 | F24: ='_Engine_R50'!M218 | G24: ='_Engine_R50'!M219 | H24: ='_Engine_R50'!M220 | I24: ='_Engine_R50'!M221 | J24: ='_Engine_R50'!M222 | K24: ='_Engine_R50'!M223 | L24: ='_Engine_R50'!M224 | M24: ='_Engine_R50'!M225 | N24: ='_Engine_R50'!M226 | O24: ='_Engine_R50'!M227 | P24: ='_Engine_R50'!M228 | Q24: ='_Engine_R50'!M229
A25: Distributable Cash | B25: =SUM(C25:Q25) | C25: ='_Engine_R50'!P215 | D25: ='_Engine_R50'!P216 | E25: ='_Engine_R50'!P217 | F25: ='_Engine_R50'!P218 | G25: ='_Engine_R50'!P219 | H25: ='_Engine_R50'!P220 | I25: ='_Engine_R50'!P221 | J25: ='_Engine_R50'!P222 | K25: ='_Engine_R50'!P223 | L25: ='_Engine_R50'!P224 | M25: ='_Engine_R50'!P225 | N25: ='_Engine_R50'!P226 | O25: ='_Engine_R50'!P227 | P25: ='_Engine_R50'!P228 | Q25: ='_Engine_R50'!P229
A26: Cumulative Distributable | B26: =Q26 | C26: =C25 | D26: =C26+D25 | E26: =D26+E25 | F26: =E26+F25 | G26: =F26+G25 | H26: =G26+H25 | I26: =H26+I25 | J26: =I26+J25 | K26: =J26+K25 | ... Q26: =P26+Q25

Sheet 4g. Annual P&L (100% Recycle)
A1: PRESS CAPITAL -- FUND I P&L | 100% RECYCLE x 36mo | I1: ="Active scenario: " & '1. Press Assumptions'!$B$136 & " (toggle on Tab 1 B136)"
A2: 9 deals @ $24M ARR. 100% retained M1-36.. LIVE from _Engine_R100.
A3: ($mm) | B3: Total | C3: Year 1 | D3: Year 2 | E3: Year 3 | F3: Year 4 | G3: Year 5 | H3: Year 6 | I3: Year 7 | J3: Year 8 | K3: Year 9 | L3: Year 10 | M3: Year 11 | N3: Year 12 | O3: Year 13 | P3: Year 14 | Q3: Year 15
A5: Revenue | B5: =SUM(C5:Q5) | C5: ='_Engine_R100'!B215 | D5: ='_Engine_R100'!B216 | E5: ='_Engine_R100'!B217 | F5: ='_Engine_R100'!B218 | G5: ='_Engine_R100'!B219 | H5: ='_Engine_R100'!B220 | I5: ='_Engine_R100'!B221 | J5: ='_Engine_R100'!B222 | K5: ='_Engine_R100'!B223 | L5: ='_Engine_R100'!B224 | M5: ='_Engine_R100'!B225 | N5: ='_Engine_R100'!B226 | O5: ='_Engine_R100'!B227 | P5: ='_Engine_R100'!B228 | Q5: ='_Engine_R100'!B229
A6: Cost of Goods Sold | B6: =SUM(C6:Q6) | C6: ='_Engine_R100'!C215 | D6: ='_Engine_R100'!C216 | E6: ='_Engine_R100'!C217 | F6: ='_Engine_R100'!C218 | G6: ='_Engine_R100'!C219 | H6: ='_Engine_R100'!C220 | I6: ='_Engine_R100'!C221 | J6: ='_Engine_R100'!C222 | K6: ='_Engine_R100'!C223 | L6: ='_Engine_R100'!C224 | M6: ='_Engine_R100'!C225 | N6: ='_Engine_R100'!C226 | O6: ='_Engine_R100'!C227 | P6: ='_Engine_R100'!C228 | Q6: ='_Engine_R100'!C229
A7: Gross Profit | B7: =SUM(C7:Q7) | C7: =C5-C6 | D7: =D5-D6 | E7: =E5-E6 | F7: =F5-F6 | G7: =G5-G6 | H7: =H5-H6 | I7: =I5-I6 | J7: =J5-J6 | ... Q7: =Q5-Q6
A9: Operating Expenses
A10: Vendor Costs | B10: =SUM(C10:Q10) | C10: ='_Engine_R100'!D215 | D10: ='_Engine_R100'!D216 | E10: ='_Engine_R100'!D217 | F10: ='_Engine_R100'!D218 | G10: ='_Engine_R100'!D219 | H10: ='_Engine_R100'!D220 | I10: ='_Engine_R100'!D221 | J10: ='_Engine_R100'!D222 | K10: ='_Engine_R100'!D223 | L10: ='_Engine_R100'!D224 | M10: ='_Engine_R100'!D225 | N10: ='_Engine_R100'!D226 | O10: ='_Engine_R100'!D227 | P10: ='_Engine_R100'!D228 | Q10: ='_Engine_R100'!D229
A11: Corporate Allocation | B11: =SUM(C11:Q11) | C11: ='_Engine_R100'!E215 | D11: ='_Engine_R100'!E216 | E11: ='_Engine_R100'!E217 | F11: ='_Engine_R100'!E218 | G11: ='_Engine_R100'!E219 | H11: ='_Engine_R100'!E220 | I11: ='_Engine_R100'!E221 | J11: ='_Engine_R100'!E222 | K11: ='_Engine_R100'!E223 | L11: ='_Engine_R100'!E224 | M11: ='_Engine_R100'!E225 | N11: ='_Engine_R100'!E226 | O11: ='_Engine_R100'!E227 | P11: ='_Engine_R100'!E228 | Q11: ='_Engine_R100'!E229
A12: Team Compensation | B12: =SUM(C12:Q12) | C12: ='_Engine_R100'!F215 | D12: ='_Engine_R100'!F216 | E12: ='_Engine_R100'!F217 | F12: ='_Engine_R100'!F218 | G12: ='_Engine_R100'!F219 | H12: ='_Engine_R100'!F220 | I12: ='_Engine_R100'!F221 | J12: ='_Engine_R100'!F222 | K12: ='_Engine_R100'!F223 | L12: ='_Engine_R100'!F224 | M12: ='_Engine_R100'!F225 | N12: ='_Engine_R100'!F226 | O12: ='_Engine_R100'!F227 | P12: ='_Engine_R100'!F228 | Q12: ='_Engine_R100'!F229
A13: Legacy Headcount Expenses | B13: =SUM(C13:Q13) | C13: ='_Engine_R100'!G215 | D13: ='_Engine_R100'!G216 | E13: ='_Engine_R100'!G217 | F13: ='_Engine_R100'!G218 | G13: ='_Engine_R100'!G219 | H13: ='_Engine_R100'!G220 | I13: ='_Engine_R100'!G221 | J13: ='_Engine_R100'!G222 | K13: ='_Engine_R100'!G223 | L13: ='_Engine_R100'!G224 | M13: ='_Engine_R100'!G225 | N13: ='_Engine_R100'!G226 | O13: ='_Engine_R100'!G227 | P13: ='_Engine_R100'!G228 | Q13: ='_Engine_R100'!G229
A14: Bonus Pool | B14: =SUM(C14:Q14) | C14: ='_Engine_R100'!H215 | D14: ='_Engine_R100'!H216 | E14: ='_Engine_R100'!H217 | F14: ='_Engine_R100'!H218 | G14: ='_Engine_R100'!H219 | H14: ='_Engine_R100'!H220 | I14: ='_Engine_R100'!H221 | J14: ='_Engine_R100'!H222 | K14: ='_Engine_R100'!H223 | L14: ='_Engine_R100'!H224 | M14: ='_Engine_R100'!H225 | N14: ='_Engine_R100'!H226 | O14: ='_Engine_R100'!H227 | P14: ='_Engine_R100'!H228 | Q14: ='_Engine_R100'!H229
A15: Total Operating Expenses | B15: =SUM(C15:Q15) | C15: =C10+C11+C12+C13+C14 | D15: =D10+D11+D12+D13+D14 | E15: =E10+E11+E12+E13+E14 | F15: =F10+F11+F12+F13+F14 | G15: =G10+G11+G12+G13+G14 | H15: =H10+H11+H12+H13+H14 | I15: =I10+I11+I12+I13+I14 | J15: =J10+J11+J12+J13+J14 | ... Q15: =Q10+Q11+Q12+Q13+Q14
A17: EBITDA | B17: =SUM(C17:Q17) | C17: ='_Engine_R100'!I215 | D17: ='_Engine_R100'!I216 | E17: ='_Engine_R100'!I217 | F17: ='_Engine_R100'!I218 | G17: ='_Engine_R100'!I219 | H17: ='_Engine_R100'!I220 | I17: ='_Engine_R100'!I221 | J17: ='_Engine_R100'!I222 | K17: ='_Engine_R100'!I223 | L17: ='_Engine_R100'!I224 | M17: ='_Engine_R100'!I225 | N17: ='_Engine_R100'!I226 | O17: ='_Engine_R100'!I227 | P17: ='_Engine_R100'!I228 | Q17: ='_Engine_R100'!I229
A18: EBITDA Margin | B18: =B17/B5 | C18: =IF(C5=0,0,C17/C5) | D18: =IF(D5=0,0,D17/D5) | E18: =IF(E5=0,0,E17/E5) | F18: =IF(F5=0,0,F17/F5) | G18: =IF(G5=0,0,G17/G5) | H18: =IF(H5=0,0,H17/H5) | I18: =IF(I5=0,0,I17/I5) | J18: =IF(J5=0,0,J17/J5) | ... Q18: =IF(Q5=0,0,Q17/Q5)
A20: Severance (Press 50%) | B20: =SUM(C20:Q20) | C20: ='_Engine_R100'!J215 | D20: ='_Engine_R100'!J216 | E20: ='_Engine_R100'!J217 | F20: ='_Engine_R100'!J218 | G20: ='_Engine_R100'!J219 | H20: ='_Engine_R100'!J220 | I20: ='_Engine_R100'!J221 | J20: ='_Engine_R100'!J222 | K20: ='_Engine_R100'!J223 | L20: ='_Engine_R100'!J224 | M20: ='_Engine_R100'!J225 | N20: ='_Engine_R100'!J226 | O20: ='_Engine_R100'!J227 | P20: ='_Engine_R100'!J228 | Q20: ='_Engine_R100'!J229
A21: Operating Income | B21: =B17-B20 | C21: =C17-C20 | D21: =D17-D20 | E21: =E17-E20 | F21: =F17-F20 | G21: =G17-G20 | H21: =H17-H20 | I21: =I17-I20 | ... Q21: =Q17-Q20
A23: Management Fee | B23: =SUM(C23:Q23) | C23: ='_Engine_R100'!K215 | D23: ='_Engine_R100'!K216 | E23: ='_Engine_R100'!K217 | F23: ='_Engine_R100'!K218 | G23: ='_Engine_R100'!K219 | H23: ='_Engine_R100'!K220 | I23: ='_Engine_R100'!K221 | J23: ='_Engine_R100'!K222 | K23: ='_Engine_R100'!K223 | L23: ='_Engine_R100'!K224 | M23: ='_Engine_R100'!K225 | N23: ='_Engine_R100'!K226 | O23: ='_Engine_R100'!K227 | P23: ='_Engine_R100'!K228 | Q23: ='_Engine_R100'!K229
A24: Retained for Recycling (100%) | B24: =SUM(C24:Q24) | C24: ='_Engine_R100'!M215 | D24: ='_Engine_R100'!M216 | E24: ='_Engine_R100'!M217 | F24: ='_Engine_R100'!M218 | G24: ='_Engine_R100'!M219 | H24: ='_Engine_R100'!M220 | I24: ='_Engine_R100'!M221 | J24: ='_Engine_R100'!M222 | K24: ='_Engine_R100'!M223 | L24: ='_Engine_R100'!M224 | M24: ='_Engine_R100'!M225 | N24: ='_Engine_R100'!M226 | O24: ='_Engine_R100'!M227 | P24: ='_Engine_R100'!M228 | Q24: ='_Engine_R100'!M229
A25: Distributable Cash | B25: =SUM(C25:Q25) | C25: ='_Engine_R100'!P215 | D25: ='_Engine_R100'!P216 | E25: ='_Engine_R100'!P217 | F25: ='_Engine_R100'!P218 | G25: ='_Engine_R100'!P219 | H25: ='_Engine_R100'!P220 | I25: ='_Engine_R100'!P221 | J25: ='_Engine_R100'!P222 | K25: ='_Engine_R100'!P223 | L25: ='_Engine_R100'!P224 | M25: ='_Engine_R100'!P225 | N25: ='_Engine_R100'!P226 | O25: ='_Engine_R100'!P227 | P25: ='_Engine_R100'!P228 | Q25: ='_Engine_R100'!P229
A26: Cumulative Distributable | B26: =Q26 | C26: =C25 | D26: =C26+D25 | E26: =D26+E25 | F26: =E26+F25 | G26: =F26+G25 | H26: =G26+H25 | I26: =H26+I25 | J26: =I26+J25 | K26: =J26+K25 | ... Q26: =P26+Q25

Sheet 4c. Monthly P&L (No Recycle)
A1: MONTHLY P&L | 5 deals @ $24M ARR (LIVE)
A3: ($mm) | B3: M1 | C3: M2 | D3: M3 | E3: M4 | F3: M5 | G3: M6 | H3: M7 | I3: M8 | J3: M9 | K3: M10 | L3: M11 | M3: M12 | N3: M13 | O3: M14 | P3: M15 | Q3: M16 | R3: M17 | S3: M18 | T3: M19 | U3: M20 | V3: M21 | W3: M22 | X3: M23 | Y3: M24 | Z3: M25 | AA3: M26 | AB3: M27 | AC3: M28 | AD3: M29 | AE3: M30 | AF3: M31 | AG3: M32 | AH3: M33 | AI3: M34 | AJ3: M35 | AK3: M36 | AL3: M37 | AM3: M38 | AN3: M39 | AO3: M40 | AP3: M41 | AQ3: M42 | AR3: M43 | AS3: M44 | AT3: M45 | AU3: M46 | AV3: M47 | AW3: M48 | AX3: M49 | AY3: M50 | AZ3: M51 | BA3: M52 | BB3: M53 | BC3: M54 | BD3: M55 | BE3: M56 | BF3: M57 | BG3: M58 | BH3: M59 | BI3: M60 | BJ3: M61 | BK3: M62 | BL3: M63 | BM3: M64 | BN3: M65 | BO3: M66 | BP3: M67 | BQ3: M68 | BR3: M69 | BS3: M70 | BT3: M71 | BU3: M72 | BV3: M73 | BW3: M74 | BX3: M75 | BY3: M76 | BZ3: M77 | CA3: M78 | CB3: M79 | CC3: M80 | CD3: M81 | CE3: M82 | CF3: M83 | CG3: M84 | CH3: M85 | CI3: M86 | CJ3: M87 | CK3: M88 | CL3: M89 | CM3: M90 | CN3: M91 | CO3: M92 | CP3: M93 | CQ3: M94 | CR3: M95 | CS3: M96 | CT3: M97 | CU3: M98 | CV3: M99 | CW3: M100 | CX3: M101 | CY3: M102 | CZ3: M103 | DA3: M104 | DB3: M105 | DC3: M106 | DD3: M107 | DE3: M108 | DF3: M109 | DG3: M110 | DH3: M111 | DI3: M112 | DJ3: M113 | DK3: M114 | DL3: M115 | DM3: M116 | DN3: M117 | DO3: M118 | DP3: M119 | DQ3: M120 | DR3: M121 | DS3: M122 | DT3: M123 | DU3: M124 | DV3: M125 | DW3: M126 | DX3: M127 | DY3: M128 | DZ3: M129 | EA3: M130 | EB3: M131 | EC3: M132 | ED3: M133 | EE3: M134 | EF3: M135 | EG3: M136 | EH3: M137 | EI3: M138 | EJ3: M139 | EK3: M140 | EL3: M141 | EM3: M142 | EN3: M143 | EO3: M144 | EP3: M145 | EQ3: M146 | ER3: M147 | ES3: M148 | ET3: M149 | EU3: M150 | EV3: M151 | EW3: M152 | EX3: M153 | EY3: M154 | EZ3: M155 | FA3: M156 | FB3: M157 | FC3: M158 | FD3: M159 | FE3: M160 | FF3: M161 | FG3: M162 | FH3: M163 | FI3: M164 | FJ3: M165 | FK3: M166 | FL3: M167 | FM3: M168 | FN3: M169 | FO3: M170 | FP3: M171 | FQ3: M172 | FR3: M173 | FS3: M174 | FT3: M175 | FU3: M176 | FV3: M177 | FW3: M178 | FX3: M179 | FY3: M180
A5: Revenue by Deal
A6: Deal #1 | B6: ='_Engine_NR'!F31/12 | C6: ='_Engine_NR'!F32/12 | D6: ='_Engine_NR'!F33/12 | E6: ='_Engine_NR'!F34/12 | F6: ='_Engine_NR'!F35/12 | G6: ='_Engine_NR'!F36/12 | H6: ='_Engine_NR'!F37/12 | I6: ='_Engine_NR'!F38/12 | J6: ='_Engine_NR'!F39/12 | K6: ='_Engine_NR'!F40/12 | L6: ='_Engine_NR'!F41/12 | M6: ='_Engine_NR'!F42/12 | N6: ='_Engine_NR'!F43/12 | O6: ='_Engine_NR'!F44/12 | P6: ='_Engine_NR'!F45/12 | Q6: ='_Engine_NR'!F46/12 | R6: ='_Engine_NR'!F47/12 | S6: ='_Engine_NR'!F48/12 | T6: ='_Engine_NR'!F49/12 | U6: ='_Engine_NR'!F50/12 | V6: ='_Engine_NR'!F51/12 | W6: ='_Engine_NR'!F52/12 | X6: ='_Engine_NR'!F53/12 | Y6: ='_Engine_NR'!F54/12 | Z6: ='_Engine_NR'!F55/12 | AA6: ='_Engine_NR'!F56/12 | AB6: ='_Engine_NR'!F57/12 | AC6: ='_Engine_NR'!F58/12 | AD6: ='_Engine_NR'!F59/12 | AE6: ='_Engine_NR'!F60/12 | AF6: ='_Engine_NR'!F61/12 | AG6: ='_Engine_NR'!F62/12 | AH6: ='_Engine_NR'!F63/12 | AI6: ='_Engine_NR'!F64/12 | AJ6: ='_Engine_NR'!F65/12 | AK6: ='_Engine_NR'!F66/12 | AL6: ='_Engine_NR'!F67/12 | AM6: ='_Engine_NR'!F68/12 | AN6: ='_Engine_NR'!F69/12 | AO6: ='_Engine_NR'!F70/12 | AP6: ='_Engine_NR'!F71/12 | AQ6: ='_Engine_NR'!F72/12 | AR6: ='_Engine_NR'!F73/12 | AS6: ='_Engine_NR'!F74/12 | AT6: ='_Engine_NR'!F75/12 | AU6: ='_Engine_NR'!F76/12 | AV6: ='_Engine_NR'!F77/12 | AW6: ='_Engine_NR'!F78/12 | AX6: ='_Engine_NR'!F79/12 | AY6: ='_Engine_NR'!F80/12 | AZ6: ='_Engine_NR'!F81/12 | BA6: ='_Engine_NR'!F82/12 | BB6: ='_Engine_NR'!F83/12 | BC6: ='_Engine_NR'!F84/12 | BD6: ='_Engine_NR'!F85/12 | BE6: ='_Engine_NR'!F86/12 | BF6: ='_Engine_NR'!F87/12 | BG6: ='_Engine_NR'!F88/12 | BH6: ='_Engine_NR'!F89/12 | BI6: ='_Engine_NR'!F90/12 | BJ6: ='_Engine_NR'!F91/12 | BK6: ='_Engine_NR'!F92/12 | BL6: ='_Engine_NR'!F93/12 | BM6: ='_Engine_NR'!F94/12 | BN6: ='_Engine_NR'!F95/12 | BO6: ='_Engine_NR'!F96/12 | BP6: ='_Engine_NR'!F97/12 | BQ6: ='_Engine_NR'!F98/12 | BR6: ='_Engine_NR'!F99/12 | BS6: ='_Engine_NR'!F100/12 | BT6: ='_Engine_NR'!F101/12 | BU6: ='_Engine_NR'!F102/12 | BV6: ='_Engine_NR'!F103/12 | BW6: ='_Engine_NR'!F104/12 | BX6: ='_Engine_NR'!F105/12 | BY6: ='_Engine_NR'!F106/12 | BZ6: ='_Engine_NR'!F107/12 | CA6: ='_Engine_NR'!F108/12 | CB6: ='_Engine_NR'!F109/12 | CC6: ='_Engine_NR'!F110/12 | CD6: ='_Engine_NR'!F111/12 | CE6: ='_Engine_NR'!F112/12 | CF6: ='_Engine_NR'!F113/12 | CG6: ='_Engine_NR'!F114/12 | CH6: ='_Engine_NR'!F115/12 | CI6: ='_Engine_NR'!F116/12 | CJ6: ='_Engine_NR'!F117/12 | CK6: ='_Engine_NR'!F118/12 | CL6: ='_Engine_NR'!F119/12 | CM6: ='_Engine_NR'!F120/12 | CN6: ='_Engine_NR'!F121/12 | CO6: ='_Engine_NR'!F122/12 | CP6: ='_Engine_NR'!F123/12 | CQ6: ='_Engine_NR'!F124/12 | CR6: ='_Engine_NR'!F125/12 | CS6: ='_Engine_NR'!F126/12 | CT6: ='_Engine_NR'!F127/12 | CU6: ='_Engine_NR'!F128/12 | CV6: ='_Engine_NR'!F129/12 | CW6: ='_Engine_NR'!F130/12 | CX6: ='_Engine_NR'!F131/12 | CY6: ='_Engine_NR'!F132/12 | CZ6: ='_Engine_NR'!F133/12 | DA6: ='_Engine_NR'!F134/12 | DB6: ='_Engine_NR'!F135/12 | DC6: ='_Engine_NR'!F136/12 | DD6: ='_Engine_NR'!F137/12 | DE6: ='_Engine_NR'!F138/12 | DF6: ='_Engine_NR'!F139/12 | DG6: ='_Engine_NR'!F140/12 | DH6: ='_Engine_NR'!F141/12 | DI6: ='_Engine_NR'!F142/12 | DJ6: ='_Engine_NR'!F143/12 | DK6: ='_Engine_NR'!F144/12 | DL6: ='_Engine_NR'!F145/12 | DM6: ='_Engine_NR'!F146/12 | DN6: ='_Engine_NR'!F147/12 | DO6: ='_Engine_NR'!F148/12 | DP6: ='_Engine_NR'!F149/12 | DQ6: ='_Engine_NR'!F150/12 | DR6: ='_Engine_NR'!F151/12 | DS6: ='_Engine_NR'!F152/12 | DT6: ='_Engine_NR'!F153/12 | DU6: ='_Engine_NR'!F154/12 | DV6: ='_Engine_NR'!F155/12 | DW6: ='_Engine_NR'!F156/12 | DX6: ='_Engine_NR'!F157/12 | DY6: ='_Engine_NR'!F158/12 | DZ6: ='_Engine_NR'!F159/12 | EA6: ='_Engine_NR'!F160/12 | EB6: ='_Engine_NR'!F161/12 | EC6: ='_Engine_NR'!F162/12 | ED6: ='_Engine_NR'!F163/12 | EE6: ='_Engine_NR'!F164/12 | EF6: ='_Engine_NR'!F165/12 | EG6: ='_Engine_NR'!F166/12 | EH6: ='_Engine_NR'!F167/12 | EI6: ='_Engine_NR'!F168/12 | EJ6: ='_Engine_NR'!F169/12 | EK6: ='_Engine_NR'!F170/12 | EL6: ='_Engine_NR'!F171/12 | EM6: ='_Engine_NR'!F172/12 | EN6: ='_Engine_NR'!F173/12 | EO6: ='_Engine_NR'!F174/12 | EP6: ='_Engine_NR'!F175/12 | EQ6: ='_Engine_NR'!F176/12 | ER6: ='_Engine_NR'!F177/12 | ES6: ='_Engine_NR'!F178/12 | ET6: ='_Engine_NR'!F179/12 | EU6: ='_Engine_NR'!F180/12 | EV6: ='_Engine_NR'!F181/12 | EW6: ='_Engine_NR'!F182/12 | EX6: ='_Engine_NR'!F183/12 | EY6: ='_Engine_NR'!F184/12 | EZ6: ='_Engine_NR'!F185/12 | FA6: ='_Engine_NR'!F186/12 | FB6: ='_Engine_NR'!F187/12 | FC6: ='_Engine_NR'!F188/12 | FD6: ='_Engine_NR'!F189/12 | FE6: ='_Engine_NR'!F190/12 | FF6: ='_Engine_NR'!F191/12 | FG6: ='_Engine_NR'!F192/12 | FH6: ='_Engine_NR'!F193/12 | FI6: ='_Engine_NR'!F194/12 | FJ6: ='_Engine_NR'!F195/12 | FK6: ='_Engine_NR'!F196/12 | FL6: ='_Engine_NR'!F197/12 | FM6: ='_Engine_NR'!F198/12 | FN6: ='_Engine_NR'!F199/12 | FO6: ='_Engine_NR'!F200/12 | FP6: ='_Engine_NR'!F201/12 | FQ6: ='_Engine_NR'!F202/12 | FR6: ='_Engine_NR'!F203/12 | FS6: ='_Engine_NR'!F204/12 | FT6: ='_Engine_NR'!F205/12 | FU6: ='_Engine_NR'!F206/12 | FV6: ='_Engine_NR'!F207/12 | FW6: ='_Engine_NR'!F208/12 | FX6: ='_Engine_NR'!F209/12 | FY6: ='_Engine_NR'!F210/12
A7: Deal #2 | B7: ='_Engine_NR'!G31/12 | C7: ='_Engine_NR'!G32/12 | D7: ='_Engine_NR'!G33/12 | E7: ='_Engine_NR'!G34/12 | F7: ='_Engine_NR'!G35/12 | G7: ='_Engine_NR'!G36/12 | H7: ='_Engine_NR'!G37/12 | I7: ='_Engine_NR'!G38/12 | J7: ='_Engine_NR'!G39/12 | K7: ='_Engine_NR'!G40/12 | L7: ='_Engine_NR'!G41/12 | M7: ='_Engine_NR'!G42/12 | N7: ='_Engine_NR'!G43/12 | O7: ='_Engine_NR'!G44/12 | P7: ='_Engine_NR'!G45/12 | Q7: ='_Engine_NR'!G46/12 | R7: ='_Engine_NR'!G47/12 | S7: ='_Engine_NR'!G48/12 | T7: ='_Engine_NR'!G49/12 | U7: ='_Engine_NR'!G50/12 | V7: ='_Engine_NR'!G51/12 | W7: ='_Engine_NR'!G52/12 | X7: ='_Engine_NR'!G53/12 | Y7: ='_Engine_NR'!G54/12 | Z7: ='_Engine_NR'!G55/12 | AA7: ='_Engine_NR'!G56/12 | AB7: ='_Engine_NR'!G57/12 | AC7: ='_Engine_NR'!G58/12 | AD7: ='_Engine_NR'!G59/12 | AE7: ='_Engine_NR'!G60/12 | AF7: ='_Engine_NR'!G61/12 | AG7: ='_Engine_NR'!G62/12 | AH7: ='_Engine_NR'!G63/12 | AI7: ='_Engine_NR'!G64/12 | AJ7: ='_Engine_NR'!G65/12 | AK7: ='_Engine_NR'!G66/12 | AL7: ='_Engine_NR'!G67/12 | AM7: ='_Engine_NR'!G68/12 | AN7: ='_Engine_NR'!G69/12 | AO7: ='_Engine_NR'!G70/12 | AP7: ='_Engine_NR'!G71/12 | AQ7: ='_Engine_NR'!G72/12 | AR7: ='_Engine_NR'!G73/12 | AS7: ='_Engine_NR'!G74/12 | AT7: ='_Engine_NR'!G75/12 | AU7: ='_Engine_NR'!G76/12 | AV7: ='_Engine_NR'!G77/12 | AW7: ='_Engine_NR'!G78/12 | AX7: ='_Engine_NR'!G79/12 | AY7: ='_Engine_NR'!G80/12 | AZ7: ='_Engine_NR'!G81/12 | BA7: ='_Engine_NR'!G82/12 | BB7: ='_Engine_NR'!G83/12 | BC7: ='_Engine_NR'!G84/12 | BD7: ='_Engine_NR'!G85/12 | BE7: ='_Engine_NR'!G86/12 | BF7: ='_Engine_NR'!G87/12 | BG7: ='_Engine_NR'!G88/12 | BH7: ='_Engine_NR'!G89/12 | BI7: ='_Engine_NR'!G90/12 | BJ7: ='_Engine_NR'!G91/12 | BK7: ='_Engine_NR'!G92/12 | BL7: ='_Engine_NR'!G93/12 | BM7: ='_Engine_NR'!G94/12 | BN7: ='_Engine_NR'!G95/12 | BO7: ='_Engine_NR'!G96/12 | BP7: ='_Engine_NR'!G97/12 | BQ7: ='_Engine_NR'!G98/12 | BR7: ='_Engine_NR'!G99/12 | BS7: ='_Engine_NR'!G100/12 | BT7: ='_Engine_NR'!G101/12 | BU7: ='_Engine_NR'!G102/12 | BV7: ='_Engine_NR'!G103/12 | BW7: ='_Engine_NR'!G104/12 | BX7: ='_Engine_NR'!G105/12 | BY7: ='_Engine_NR'!G106/12 | BZ7: ='_Engine_NR'!G107/12 | CA7: ='_Engine_NR'!G108/12 | CB7: ='_Engine_NR'!G109/12 | CC7: ='_Engine_NR'!G110/12 | CD7: ='_Engine_NR'!G111/12 | CE7: ='_Engine_NR'!G112/12 | CF7: ='_Engine_NR'!G113/12 | CG7: ='_Engine_NR'!G114/12 | CH7: ='_Engine_NR'!G115/12 | CI7: ='_Engine_NR'!G116/12 | CJ7: ='_Engine_NR'!G117/12 | CK7: ='_Engine_NR'!G118/12 | CL7: ='_Engine_NR'!G119/12 | CM7: ='_Engine_NR'!G120/12 | CN7: ='_Engine_NR'!G121/12 | CO7: ='_Engine_NR'!G122/12 | CP7: ='_Engine_NR'!G123/12 | CQ7: ='_Engine_NR'!G124/12 | CR7: ='_Engine_NR'!G125/12 | CS7: ='_Engine_NR'!G126/12 | CT7: ='_Engine_NR'!G127/12 | CU7: ='_Engine_NR'!G128/12 | CV7: ='_Engine_NR'!G129/12 | CW7: ='_Engine_NR'!G130/12 | CX7: ='_Engine_NR'!G131/12 | CY7: ='_Engine_NR'!G132/12 | CZ7: ='_Engine_NR'!G133/12 | DA7: ='_Engine_NR'!G134/12 | DB7: ='_Engine_NR'!G135/12 | DC7: ='_Engine_NR'!G136/12 | DD7: ='_Engine_NR'!G137/12 | DE7: ='_Engine_NR'!G138/12 | DF7: ='_Engine_NR'!G139/12 | DG7: ='_Engine_NR'!G140/12 | DH7: ='_Engine_NR'!G141/12 | DI7: ='_Engine_NR'!G142/12 | DJ7: ='_Engine_NR'!G143/12 | DK7: ='_Engine_NR'!G144/12 | DL7: ='_Engine_NR'!G145/12 | DM7: ='_Engine_NR'!G146/12 | DN7: ='_Engine_NR'!G147/12 | DO7: ='_Engine_NR'!G148/12 | DP7: ='_Engine_NR'!G149/12 | DQ7: ='_Engine_NR'!G150/12 | DR7: ='_Engine_NR'!G151/12 | DS7: ='_Engine_NR'!G152/12 | DT7: ='_Engine_NR'!G153/12 | DU7: ='_Engine_NR'!G154/12 | DV7: ='_Engine_NR'!G155/12 | DW7: ='_Engine_NR'!G156/12 | DX7: ='_Engine_NR'!G157/12 | DY7: ='_Engine_NR'!G158/12 | DZ7: ='_Engine_NR'!G159/12 | EA7: ='_Engine_NR'!G160/12 | EB7: ='_Engine_NR'!G161/12 | EC7: ='_Engine_NR'!G162/12 | ED7: ='_Engine_NR'!G163/12 | EE7: ='_Engine_NR'!G164/12 | EF7: ='_Engine_NR'!G165/12 | EG7: ='_Engine_NR'!G166/12 | EH7: ='_Engine_NR'!G167/12 | EI7: ='_Engine_NR'!G168/12 | EJ7: ='_Engine_NR'!G169/12 | EK7: ='_Engine_NR'!G170/12 | EL7: ='_Engine_NR'!G171/12 | EM7: ='_Engine_NR'!G172/12 | EN7: ='_Engine_NR'!G173/12 | EO7: ='_Engine_NR'!G174/12 | EP7: ='_Engine_NR'!G175/12 | EQ7: ='_Engine_NR'!G176/12 | ER7: ='_Engine_NR'!G177/12 | ES7: ='_Engine_NR'!G178/12 | ET7: ='_Engine_NR'!G179/12 | EU7: ='_Engine_NR'!G180/12 | EV7: ='_Engine_NR'!G181/12 | EW7: ='_Engine_NR'!G182/12 | EX7: ='_Engine_NR'!G183/12 | EY7: ='_Engine_NR'!G184/12 | EZ7: ='_Engine_NR'!G185/12 | FA7: ='_Engine_NR'!G186/12 | FB7: ='_Engine_NR'!G187/12 | FC7: ='_Engine_NR'!G188/12 | FD7: ='_Engine_NR'!G189/12 | FE7: ='_Engine_NR'!G190/12 | FF7: ='_Engine_NR'!G191/12 | FG7: ='_Engine_NR'!G192/12 | FH7: ='_Engine_NR'!G193/12 | FI7: ='_Engine_NR'!G194/12 | FJ7: ='_Engine_NR'!G195/12 | FK7: ='_Engine_NR'!G196/12 | FL7: ='_Engine_NR'!G197/12 | FM7: ='_Engine_NR'!G198/12 | FN7: ='_Engine_NR'!G199/12 | FO7: ='_Engine_NR'!G200/12 | FP7: ='_Engine_NR'!G201/12 | FQ7: ='_Engine_NR'!G202/12 | FR7: ='_Engine_NR'!G203/12 | FS7: ='_Engine_NR'!G204/12 | FT7: ='_Engine_NR'!G205/12 | FU7: ='_Engine_NR'!G206/12 | FV7: ='_Engine_NR'!G207/12 | FW7: ='_Engine_NR'!G208/12 | FX7: ='_Engine_NR'!G209/12 | FY7: ='_Engine_NR'!G210/12
A8: Deal #3 | B8: ='_Engine_NR'!H31/12 | C8: ='_Engine_NR'!H32/12 | D8: ='_Engine_NR'!H33/12 | E8: ='_Engine_NR'!H34/12 | F8: ='_Engine_NR'!H35/12 | G8: ='_Engine_NR'!H36/12 | H8: ='_Engine_NR'!H37/12 | I8: ='_Engine_NR'!H38/12 | J8: ='_Engine_NR'!H39/12 | K8: ='_Engine_NR'!H40/12 | L8: ='_Engine_NR'!H41/12 | M8: ='_Engine_NR'!H42/12 | N8: ='_Engine_NR'!H43/12 | O8: ='_Engine_NR'!H44/12 | P8: ='_Engine_NR'!H45/12 | Q8: ='_Engine_NR'!H46/12 | R8: ='_Engine_NR'!H47/12 | S8: ='_Engine_NR'!H48/12 | T8: ='_Engine_NR'!H49/12 | U8: ='_Engine_NR'!H50/12 | V8: ='_Engine_NR'!H51/12 | W8: ='_Engine_NR'!H52/12 | X8: ='_Engine_NR'!H53/12 | Y8: ='_Engine_NR'!H54/12 | Z8: ='_Engine_NR'!H55/12 | AA8: ='_Engine_NR'!H56/12 | AB8: ='_Engine_NR'!H57/12 | AC8: ='_Engine_NR'!H58/12 | AD8: ='_Engine_NR'!H59/12 | AE8: ='_Engine_NR'!H60/12 | AF8: ='_Engine_NR'!H61/12 | AG8: ='_Engine_NR'!H62/12 | AH8: ='_Engine_NR'!H63/12 | AI8: ='_Engine_NR'!H64/12 | AJ8: ='_Engine_NR'!H65/12 | AK8: ='_Engine_NR'!H66/12 | AL8: ='_Engine_NR'!H67/12 | AM8: ='_Engine_NR'!H68/12 | AN8: ='_Engine_NR'!H69/12 | AO8: ='_Engine_NR'!H70/12 | AP8: ='_Engine_NR'!H71/12 | AQ8: ='_Engine_NR'!H72/12 | AR8: ='_Engine_NR'!H73/12 | AS8: ='_Engine_NR'!H74/12 | AT8: ='_Engine_NR'!H75/12 | AU8: ='_Engine_NR'!H76/12 | AV8: ='_Engine_NR'!H77/12 | AW8: ='_Engine_NR'!H78/12 | AX8: ='_Engine_NR'!H79/12 | AY8: ='_Engine_NR'!H80/12 | AZ8: ='_Engine_NR'!H81/12 | BA8: ='_Engine_NR'!H82/12 | BB8: ='_Engine_NR'!H83/12 | BC8: ='_Engine_NR'!H84/12 | BD8: ='_Engine_NR'!H85/12 | BE8: ='_Engine_NR'!H86/12 | BF8: ='_Engine_NR'!H87/12 | BG8: ='_Engine_NR'!H88/12 | BH8: ='_Engine_NR'!H89/12 | BI8: ='_Engine_NR'!H90/12 | BJ8: ='_Engine_NR'!H91/12 | BK8: ='_Engine_NR'!H92/12 | BL8: ='_Engine_NR'!H93/12 | BM8: ='_Engine_NR'!H94/12 | BN8: ='_Engine_NR'!H95/12 | BO8: ='_Engine_NR'!H96/12 | BP8: ='_Engine_NR'!H97/12 | BQ8: ='_Engine_NR'!H98/12 | BR8: ='_Engine_NR'!H99/12 | BS8: ='_Engine_NR'!H100/12 | BT8: ='_Engine_NR'!H101/12 | BU8: ='_Engine_NR'!H102/12 | BV8: ='_Engine_NR'!H103/12 | BW8: ='_Engine_NR'!H104/12 | BX8: ='_Engine_NR'!H105/12 | BY8: ='_Engine_NR'!H106/12 | BZ8: ='_Engine_NR'!H107/12 | CA8: ='_Engine_NR'!H108/12 | CB8: ='_Engine_NR'!H109/12 | CC8: ='_Engine_NR'!H110/12 | CD8: ='_Engine_NR'!H111/12 | CE8: ='_Engine_NR'!H112/12 | CF8: ='_Engine_NR'!H113/12 | CG8: ='_Engine_NR'!H114/12 | CH8: ='_Engine_NR'!H115/12 | CI8: ='_Engine_NR'!H116/12 | CJ8: ='_Engine_NR'!H117/12 | CK8: ='_Engine_NR'!H118/12 | CL8: ='_Engine_NR'!H119/12 | CM8: ='_Engine_NR'!H120/12 | CN8: ='_Engine_NR'!H121/12 | CO8: ='_Engine_NR'!H122/12 | CP8: ='_Engine_NR'!H123/12 | CQ8: ='_Engine_NR'!H124/12 | CR8: ='_Engine_NR'!H125/12 | CS8: ='_Engine_NR'!H126/12 | CT8: ='_Engine_NR'!H127/12 | CU8: ='_Engine_NR'!H128/12 | CV8: ='_Engine_NR'!H129/12 | CW8: ='_Engine_NR'!H130/12 | CX8: ='_Engine_NR'!H131/12 | CY8: ='_Engine_NR'!H132/12 | CZ8: ='_Engine_NR'!H133/12 | DA8: ='_Engine_NR'!H134/12 | DB8: ='_Engine_NR'!H135/12 | DC8: ='_Engine_NR'!H136/12 | DD8: ='_Engine_NR'!H137/12 | DE8: ='_Engine_NR'!H138/12 | DF8: ='_Engine_NR'!H139/12 | DG8: ='_Engine_NR'!H140/12 | DH8: ='_Engine_NR'!H141/12 | DI8: ='_Engine_NR'!H142/12 | DJ8: ='_Engine_NR'!H143/12 | DK8: ='_Engine_NR'!H144/12 | DL8: ='_Engine_NR'!H145/12 | DM8: ='_Engine_NR'!H146/12 | DN8: ='_Engine_NR'!H147/12 | DO8: ='_Engine_NR'!H148/12 | DP8: ='_Engine_NR'!H149/12 | DQ8: ='_Engine_NR'!H150/12 | DR8: ='_Engine_NR'!H151/12 | DS8: ='_Engine_NR'!H152/12 | DT8: ='_Engine_NR'!H153/12 | DU8: ='_Engine_NR'!H154/12 | DV8: ='_Engine_NR'!H155/12 | DW8: ='_Engine_NR'!H156/12 | DX8: ='_Engine_NR'!H157/12 | DY8: ='_Engine_NR'!H158/12 | DZ8: ='_Engine_NR'!H159/12 | EA8: ='_Engine_NR'!H160/12 | EB8: ='_Engine_NR'!H161/12 | EC8: ='_Engine_NR'!H162/12 | ED8: ='_Engine_NR'!H163/12 | EE8: ='_Engine_NR'!H164/12 | EF8: ='_Engine_NR'!H165/12 | EG8: ='_Engine_NR'!H166/12 | EH8: ='_Engine_NR'!H167/12 | EI8: ='_Engine_NR'!H168/12 | EJ8: ='_Engine_NR'!H169/12 | EK8: ='_Engine_NR'!H170/12 | EL8: ='_Engine_NR'!H171/12 | EM8: ='_Engine_NR'!H172/12 | EN8: ='_Engine_NR'!H173/12 | EO8: ='_Engine_NR'!H174/12 | EP8: ='_Engine_NR'!H175/12 | EQ8: ='_Engine_NR'!H176/12 | ER8: ='_Engine_NR'!H177/12 | ES8: ='_Engine_NR'!H178/12 | ET8: ='_Engine_NR'!H179/12 | EU8: ='_Engine_NR'!H180/12 | EV8: ='_Engine_NR'!H181/12 | EW8: ='_Engine_NR'!H182/12 | EX8: ='_Engine_NR'!H183/12 | EY8: ='_Engine_NR'!H184/12 | EZ8: ='_Engine_NR'!H185/12 | FA8: ='_Engine_NR'!H186/12 | FB8: ='_Engine_NR'!H187/12 | FC8: ='_Engine_NR'!H188/12 | FD8: ='_Engine_NR'!H189/12 | FE8: ='_Engine_NR'!H190/12 | FF8: ='_Engine_NR'!H191/12 | FG8: ='_Engine_NR'!H192/12 | FH8: ='_Engine_NR'!H193/12 | FI8: ='_Engine_NR'!H194/12 | FJ8: ='_Engine_NR'!H195/12 | FK8: ='_Engine_NR'!H196/12 | FL8: ='_Engine_NR'!H197/12 | FM8: ='_Engine_NR'!H198/12 | FN8: ='_Engine_NR'!H199/12 | FO8: ='_Engine_NR'!H200/12 | FP8: ='_Engine_NR'!H201/12 | FQ8: ='_Engine_NR'!H202/12 | FR8: ='_Engine_NR'!H203/12 | FS8: ='_Engine_NR'!H204/12 | FT8: ='_Engine_NR'!H205/12 | FU8: ='_Engine_NR'!H206/12 | FV8: ='_Engine_NR'!H207/12 | FW8: ='_Engine_NR'!H208/12 | FX8: ='_Engine_NR'!H209/12 | FY8: ='_Engine_NR'!H210/12
A9: Deal #4 | B9: ='_Engine_NR'!I31/12 | C9: ='_Engine_NR'!I32/12 | D9: ='_Engine_NR'!I33/12 | E9: ='_Engine_NR'!I34/12 | F9: ='_Engine_NR'!I35/12 | G9: ='_Engine_NR'!I36/12 | H9: ='_Engine_NR'!I37/12 | I9: ='_Engine_NR'!I38/12 | J9: ='_Engine_NR'!I39/12 | K9: ='_Engine_NR'!I40/12 | L9: ='_Engine_NR'!I41/12 | M9: ='_Engine_NR'!I42/12 | N9: ='_Engine_NR'!I43/12 | O9: ='_Engine_NR'!I44/12 | P9: ='_Engine_NR'!I45/12 | Q9: ='_Engine_NR'!I46/12 | R9: ='_Engine_NR'!I47/12 | S9: ='_Engine_NR'!I48/12 | T9: ='_Engine_NR'!I49/12 | U9: ='_Engine_NR'!I50/12 | V9: ='_Engine_NR'!I51/12 | W9: ='_Engine_NR'!I52/12 | X9: ='_Engine_NR'!I53/12 | Y9: ='_Engine_NR'!I54/12 | Z9: ='_Engine_NR'!I55/12 | AA9: ='_Engine_NR'!I56/12 | AB9: ='_Engine_NR'!I57/12 | AC9: ='_Engine_NR'!I58/12 | AD9: ='_Engine_NR'!I59/12 | AE9: ='_Engine_NR'!I60/12 | AF9: ='_Engine_NR'!I61/12 | AG9: ='_Engine_NR'!I62/12 | AH9: ='_Engine_NR'!I63/12 | AI9: ='_Engine_NR'!I64/12 | AJ9: ='_Engine_NR'!I65/12 | AK9: ='_Engine_NR'!I66/12 | AL9: ='_Engine_NR'!I67/12 | AM9: ='_Engine_NR'!I68/12 | AN9: ='_Engine_NR'!I69/12 | AO9: ='_Engine_NR'!I70/12 | AP9: ='_Engine_NR'!I71/12 | AQ9: ='_Engine_NR'!I72/12 | AR9: ='_Engine_NR'!I73/12 | AS9: ='_Engine_NR'!I74/12 | AT9: ='_Engine_NR'!I75/12 | AU9: ='_Engine_NR'!I76/12 | AV9: ='_Engine_NR'!I77/12 | AW9: ='_Engine_NR'!I78/12 | AX9: ='_Engine_NR'!I79/12 | AY9: ='_Engine_NR'!I80/12 | AZ9: ='_Engine_NR'!I81/12 | BA9: ='_Engine_NR'!I82/12 | BB9: ='_Engine_NR'!I83/12 | BC9: ='_Engine_NR'!I84/12 | BD9: ='_Engine_NR'!I85/12 | BE9: ='_Engine_NR'!I86/12 | BF9: ='_Engine_NR'!I87/12 | BG9: ='_Engine_NR'!I88/12 | BH9: ='_Engine_NR'!I89/12 | BI9: ='_Engine_NR'!I90/12 | BJ9: ='_Engine_NR'!I91/12 | BK9: ='_Engine_NR'!I92/12 | BL9: ='_Engine_NR'!I93/12 | BM9: ='_Engine_NR'!I94/12 | BN9: ='_Engine_NR'!I95/12 | BO9: ='_Engine_NR'!I96/12 | BP9: ='_Engine_NR'!I97/12 | BQ9: ='_Engine_NR'!I98/12 | BR9: ='_Engine_NR'!I99/12 | BS9: ='_Engine_NR'!I100/12 | BT9: ='_Engine_NR'!I101/12 | BU9: ='_Engine_NR'!I102/12 | BV9: ='_Engine_NR'!I103/12 | BW9: ='_Engine_NR'!I104/12 | BX9: ='_Engine_NR'!I105/12 | BY9: ='_Engine_NR'!I106/12 | BZ9: ='_Engine_NR'!I107/12 | CA9: ='_Engine_NR'!I108/12 | CB9: ='_Engine_NR'!I109/12 | CC9: ='_Engine_NR'!I110/12 | CD9: ='_Engine_NR'!I111/12 | CE9: ='_Engine_NR'!I112/12 | CF9: ='_Engine_NR'!I113/12 | CG9: ='_Engine_NR'!I114/12 | CH9: ='_Engine_NR'!I115/12 | CI9: ='_Engine_NR'!I116/12 | CJ9: ='_Engine_NR'!I117/12 | CK9: ='_Engine_NR'!I118/12 | CL9: ='_Engine_NR'!I119/12 | CM9: ='_Engine_NR'!I120/12 | CN9: ='_Engine_NR'!I121/12 | CO9: ='_Engine_NR'!I122/12 | CP9: ='_Engine_NR'!I123/12 | CQ9: ='_Engine_NR'!I124/12 | CR9: ='_Engine_NR'!I125/12 | CS9: ='_Engine_NR'!I126/12 | CT9: ='_Engine_NR'!I127/12 | CU9: ='_Engine_NR'!I128/12 | CV9: ='_Engine_NR'!I129/12 | CW9: ='_Engine_NR'!I130/12 | CX9: ='_Engine_NR'!I131/12 | CY9: ='_Engine_NR'!I132/12 | CZ9: ='_Engine_NR'!I133/12 | DA9: ='_Engine_NR'!I134/12 | DB9: ='_Engine_NR'!I135/12 | DC9: ='_Engine_NR'!I136/12 | DD9: ='_Engine_NR'!I137/12 | DE9: ='_Engine_NR'!I138/12 | DF9: ='_Engine_NR'!I139/12 | DG9: ='_Engine_NR'!I140/12 | DH9: ='_Engine_NR'!I141/12 | DI9: ='_Engine_NR'!I142/12 | DJ9: ='_Engine_NR'!I143/12 | DK9: ='_Engine_NR'!I144/12 | DL9: ='_Engine_NR'!I145/12 | DM9: ='_Engine_NR'!I146/12 | DN9: ='_Engine_NR'!I147/12 | DO9: ='_Engine_NR'!I148/12 | DP9: ='_Engine_NR'!I149/12 | DQ9: ='_Engine_NR'!I150/12 | DR9: ='_Engine_NR'!I151/12 | DS9: ='_Engine_NR'!I152/12 | DT9: ='_Engine_NR'!I153/12 | DU9: ='_Engine_NR'!I154/12 | DV9: ='_Engine_NR'!I155/12 | DW9: ='_Engine_NR'!I156/12 | DX9: ='_Engine_NR'!I157/12 | DY9: ='_Engine_NR'!I158/12 | DZ9: ='_Engine_NR'!I159/12 | EA9: ='_Engine_NR'!I160/12 | EB9: ='_Engine_NR'!I161/12 | EC9: ='_Engine_NR'!I162/12 | ED9: ='_Engine_NR'!I163/12 | EE9: ='_Engine_NR'!I164/12 | EF9: ='_Engine_NR'!I165/12 | EG9: ='_Engine_NR'!I166/12 | EH9: ='_Engine_NR'!I167/12 | EI9: ='_Engine_NR'!I168/12 | EJ9: ='_Engine_NR'!I169/12 | EK9: ='_Engine_NR'!I170/12 | EL9: ='_Engine_NR'!I171/12 | EM9: ='_Engine_NR'!I172/12 | EN9: ='_Engine_NR'!I173/12 | EO9: ='_Engine_NR'!I174/12 | EP9: ='_Engine_NR'!I175/12 | EQ9: ='_Engine_NR'!I176/12 | ER9: ='_Engine_NR'!I177/12 | ES9: ='_Engine_NR'!I178/12 | ET9: ='_Engine_NR'!I179/12 | EU9: ='_Engine_NR'!I180/12 | EV9: ='_Engine_NR'!I181/12 | EW9: ='_Engine_NR'!I182/12 | EX9: ='_Engine_NR'!I183/12 | EY9: ='_Engine_NR'!I184/12 | EZ9: ='_Engine_NR'!I185/12 | FA9: ='_Engine_NR'!I186/12 | FB9: ='_Engine_NR'!I187/12 | FC9: ='_Engine_NR'!I188/12 | FD9: ='_Engine_NR'!I189/12 | FE9: ='_Engine_NR'!I190/12 | FF9: ='_Engine_NR'!I191/12 | FG9: ='_Engine_NR'!I192/12 | FH9: ='_Engine_NR'!I193/12 | FI9: ='_Engine_NR'!I194/12 | FJ9: ='_Engine_NR'!I195/12 | FK9: ='_Engine_NR'!I196/12 | FL9: ='_Engine_NR'!I197/12 | FM9: ='_Engine_NR'!I198/12 | FN9: ='_Engine_NR'!I199/12 | FO9: ='_Engine_NR'!I200/12 | FP9: ='_Engine_NR'!I201/12 | FQ9: ='_Engine_NR'!I202/12 | FR9: ='_Engine_NR'!I203/12 | FS9: ='_Engine_NR'!I204/12 | FT9: ='_Engine_NR'!I205/12 | FU9: ='_Engine_NR'!I206/12 | FV9: ='_Engine_NR'!I207/12 | FW9: ='_Engine_NR'!I208/12 | FX9: ='_Engine_NR'!I209/12 | FY9: ='_Engine_NR'!I210/12
A10: Deal #5 | B10: ='_Engine_NR'!J31/12 | C10: ='_Engine_NR'!J32/12 | D10: ='_Engine_NR'!J33/12 | E10: ='_Engine_NR'!J34/12 | F10: ='_Engine_NR'!J35/12 | G10: ='_Engine_NR'!J36/12 | H10: ='_Engine_NR'!J37/12 | I10: ='_Engine_NR'!J38/12 | J10: ='_Engine_NR'!J39/12 | K10: ='_Engine_NR'!J40/12 | L10: ='_Engine_NR'!J41/12 | M10: ='_Engine_NR'!J42/12 | N10: ='_Engine_NR'!J43/12 | O10: ='_Engine_NR'!J44/12 | P10: ='_Engine_NR'!J45/12 | Q10: ='_Engine_NR'!J46/12 | R10: ='_Engine_NR'!J47/12 | S10: ='_Engine_NR'!J48/12 | T10: ='_Engine_NR'!J49/12 | U10: ='_Engine_NR'!J50/12 | V10: ='_Engine_NR'!J51/12 | W10: ='_Engine_NR'!J52/12 | X10: ='_Engine_NR'!J53/12 | Y10: ='_Engine_NR'!J54/12 | Z10: ='_Engine_NR'!J55/12 | AA10: ='_Engine_NR'!J56/12 | AB10: ='_Engine_NR'!J57/12 | AC10: ='_Engine_NR'!J58/12 | AD10: ='_Engine_NR'!J59/12 | AE10: ='_Engine_NR'!J60/12 | AF10: ='_Engine_NR'!J61/12 | AG10: ='_Engine_NR'!J62/12 | AH10: ='_Engine_NR'!J63/12 | AI10: ='_Engine_NR'!J64/12 | AJ10: ='_Engine_NR'!J65/12 | AK10: ='_Engine_NR'!J66/12 | AL10: ='_Engine_NR'!J67/12 | AM10: ='_Engine_NR'!J68/12 | AN10: ='_Engine_NR'!J69/12 | AO10: ='_Engine_NR'!J70/12 | AP10: ='_Engine_NR'!J71/12 | AQ10: ='_Engine_NR'!J72/12 | AR10: ='_Engine_NR'!J73/12 | AS10: ='_Engine_NR'!J74/12 | AT10: ='_Engine_NR'!J75/12 | AU10: ='_Engine_NR'!J76/12 | AV10: ='_Engine_NR'!J77/12 | AW10: ='_Engine_NR'!J78/12 | AX10: ='_Engine_NR'!J79/12 | AY10: ='_Engine_NR'!J80/12 | AZ10: ='_Engine_NR'!J81/12 | BA10: ='_Engine_NR'!J82/12 | BB10: ='_Engine_NR'!J83/12 | BC10: ='_Engine_NR'!J84/12 | BD10: ='_Engine_NR'!J85/12 | BE10: ='_Engine_NR'!J86/12 | BF10: ='_Engine_NR'!J87/12 | BG10: ='_Engine_NR'!J88/12 | BH10: ='_Engine_NR'!J89/12 | BI10: ='_Engine_NR'!J90/12 | BJ10: ='_Engine_NR'!J91/12 | BK10: ='_Engine_NR'!J92/12 | BL10: ='_Engine_NR'!J93/12 | BM10: ='_Engine_NR'!J94/12 | BN10: ='_Engine_NR'!J95/12 | BO10: ='_Engine_NR'!J96/12 | BP10: ='_Engine_NR'!J97/12 | BQ10: ='_Engine_NR'!J98/12 | BR10: ='_Engine_NR'!J99/12 | BS10: ='_Engine_NR'!J100/12 | BT10: ='_Engine_NR'!J101/12 | BU10: ='_Engine_NR'!J102/12 | BV10: ='_Engine_NR'!J103/12 | BW10: ='_Engine_NR'!J104/12 | BX10: ='_Engine_NR'!J105/12 | BY10: ='_Engine_NR'!J106/12 | BZ10: ='_Engine_NR'!J107/12 | CA10: ='_Engine_NR'!J108/12 | CB10: ='_Engine_NR'!J109/12 | CC10: ='_Engine_NR'!J110/12 | CD10: ='_Engine_NR'!J111/12 | CE10: ='_Engine_NR'!J112/12 | CF10: ='_Engine_NR'!J113/12 | CG10: ='_Engine_NR'!J114/12 | CH10: ='_Engine_NR'!J115/12 | CI10: ='_Engine_NR'!J116/12 | CJ10: ='_Engine_NR'!J117/12 | CK10: ='_Engine_NR'!J118/12 | CL10: ='_Engine_NR'!J119/12 | CM10: ='_Engine_NR'!J120/12 | CN10: ='_Engine_NR'!J121/12 | CO10: ='_Engine_NR'!J122/12 | CP10: ='_Engine_NR'!J123/12 | CQ10: ='_Engine_NR'!J124/12 | CR10: ='_Engine_NR'!J125/12 | CS10: ='_Engine_NR'!J126/12 | CT10: ='_Engine_NR'!J127/12 | CU10: ='_Engine_NR'!J128/12 | CV10: ='_Engine_NR'!J129/12 | CW10: ='_Engine_NR'!J130/12 | CX10: ='_Engine_NR'!J131/12 | CY10: ='_Engine_NR'!J132/12 | CZ10: ='_Engine_NR'!J133/12 | DA10: ='_Engine_NR'!J134/12 | DB10: ='_Engine_NR'!J135/12 | DC10: ='_Engine_NR'!J136/12 | DD10: ='_Engine_NR'!J137/12 | DE10: ='_Engine_NR'!J138/12 | DF10: ='_Engine_NR'!J139/12 | DG10: ='_Engine_NR'!J140/12 | DH10: ='_Engine_NR'!J141/12 | DI10: ='_Engine_NR'!J142/12 | DJ10: ='_Engine_NR'!J143/12 | DK10: ='_Engine_NR'!J144/12 | DL10: ='_Engine_NR'!J145/12 | DM10: ='_Engine_NR'!J146/12 | DN10: ='_Engine_NR'!J147/12 | DO10: ='_Engine_NR'!J148/12 | DP10: ='_Engine_NR'!J149/12 | DQ10: ='_Engine_NR'!J150/12 | DR10: ='_Engine_NR'!J151/12 | DS10: ='_Engine_NR'!J152/12 | DT10: ='_Engine_NR'!J153/12 | DU10: ='_Engine_NR'!J154/12 | DV10: ='_Engine_NR'!J155/12 | DW10: ='_Engine_NR'!J156/12 | DX10: ='_Engine_NR'!J157/12 | DY10: ='_Engine_NR'!J158/12 | DZ10: ='_Engine_NR'!J159/12 | EA10: ='_Engine_NR'!J160/12 | EB10: ='_Engine_NR'!J161/12 | EC10: ='_Engine_NR'!J162/12 | ED10: ='_Engine_NR'!J163/12 | EE10: ='_Engine_NR'!J164/12 | EF10: ='_Engine_NR'!J165/12 | EG10: ='_Engine_NR'!J166/12 | EH10: ='_Engine_NR'!J167/12 | EI10: ='_Engine_NR'!J168/12 | EJ10: ='_Engine_NR'!J169/12 | EK10: ='_Engine_NR'!J170/12 | EL10: ='_Engine_NR'!J171/12 | EM10: ='_Engine_NR'!J172/12 | EN10: ='_Engine_NR'!J173/12 | EO10: ='_Engine_NR'!J174/12 | EP10: ='_Engine_NR'!J175/12 | EQ10: ='_Engine_NR'!J176/12 | ER10: ='_Engine_NR'!J177/12 | ES10: ='_Engine_NR'!J178/12 | ET10: ='_Engine_NR'!J179/12 | EU10: ='_Engine_NR'!J180/12 | EV10: ='_Engine_NR'!J181/12 | EW10: ='_Engine_NR'!J182/12 | EX10: ='_Engine_NR'!J183/12 | EY10: ='_Engine_NR'!J184/12 | EZ10: ='_Engine_NR'!J185/12 | FA10: ='_Engine_NR'!J186/12 | FB10: ='_Engine_NR'!J187/12 | FC10: ='_Engine_NR'!J188/12 | FD10: ='_Engine_NR'!J189/12 | FE10: ='_Engine_NR'!J190/12 | FF10: ='_Engine_NR'!J191/12 | FG10: ='_Engine_NR'!J192/12 | FH10: ='_Engine_NR'!J193/12 | FI10: ='_Engine_NR'!J194/12 | FJ10: ='_Engine_NR'!J195/12 | FK10: ='_Engine_NR'!J196/12 | FL10: ='_Engine_NR'!J197/12 | FM10: ='_Engine_NR'!J198/12 | FN10: ='_Engine_NR'!J199/12 | FO10: ='_Engine_NR'!J200/12 | FP10: ='_Engine_NR'!J201/12 | FQ10: ='_Engine_NR'!J202/12 | FR10: ='_Engine_NR'!J203/12 | FS10: ='_Engine_NR'!J204/12 | FT10: ='_Engine_NR'!J205/12 | FU10: ='_Engine_NR'!J206/12 | FV10: ='_Engine_NR'!J207/12 | FW10: ='_Engine_NR'!J208/12 | FX10: ='_Engine_NR'!J209/12 | FY10: ='_Engine_NR'!J210/12
A12: Portfolio P&L
